[2025-03-18T10:27:27.245+0000] {local_task_job_runner.py:123} INFO - ::group::Pre task execution logs
[2025-03-18T10:27:27.253+0000] {taskinstance.py:2614} INFO - Dependencies all met for dep_context=non-requeueable deps ti=<TaskInstance: kindle_store_etl_taskflow.extract_book_data manual__2025-03-18T10:27:25.081541+00:00 [queued]>
[2025-03-18T10:27:27.257+0000] {taskinstance.py:2614} INFO - Dependencies all met for dep_context=requeueable deps ti=<TaskInstance: kindle_store_etl_taskflow.extract_book_data manual__2025-03-18T10:27:25.081541+00:00 [queued]>
[2025-03-18T10:27:27.258+0000] {taskinstance.py:2867} INFO - Starting attempt 1 of 1
[2025-03-18T10:27:27.262+0000] {taskinstance.py:2890} INFO - Executing <Task(_PythonDecoratedOperator): extract_book_data> on 2025-03-18 10:27:25.081541+00:00
[2025-03-18T10:27:27.266+0000] {warnings.py:112} WARNING - /home/***/.local/lib/python3.12/site-packages/***/task/task_runner/standard_task_runner.py:70: DeprecationWarning: This process (pid=176) is multi-threaded, use of fork() may lead to deadlocks in the child.
  pid = os.fork()

[2025-03-18T10:27:27.267+0000] {standard_task_runner.py:72} INFO - Started process 179 to run task
[2025-03-18T10:27:27.268+0000] {standard_task_runner.py:104} INFO - Running: ['***', 'tasks', 'run', 'kindle_store_etl_taskflow', 'extract_book_data', 'manual__2025-03-18T10:27:25.081541+00:00', '--job-id', '26', '--raw', '--subdir', 'DAGS_FOLDER/etl.py', '--cfg-path', '/tmp/tmpg7sw9iqy']
[2025-03-18T10:27:27.268+0000] {standard_task_runner.py:105} INFO - Job 26: Subtask extract_book_data
[2025-03-18T10:27:27.296+0000] {task_command.py:467} INFO - Running <TaskInstance: kindle_store_etl_taskflow.extract_book_data manual__2025-03-18T10:27:25.081541+00:00 [running]> on host 1116547ce33b
[2025-03-18T10:27:27.327+0000] {taskinstance.py:3134} INFO - Exporting env vars: AIRFLOW_CTX_DAG_OWNER='***' AIRFLOW_CTX_DAG_ID='kindle_store_etl_taskflow' AIRFLOW_CTX_TASK_ID='extract_book_data' AIRFLOW_CTX_EXECUTION_DATE='2025-03-18T10:27:25.081541+00:00' AIRFLOW_CTX_TRY_NUMBER='1' AIRFLOW_CTX_DAG_RUN_ID='manual__2025-03-18T10:27:25.081541+00:00'
[2025-03-18T10:27:27.327+0000] {logging_mixin.py:190} INFO - Task instance is in running state
[2025-03-18T10:27:27.328+0000] {logging_mixin.py:190} INFO -  Previous state of the Task instance: queued
[2025-03-18T10:27:27.328+0000] {logging_mixin.py:190} INFO - Current task name:extract_book_data state:running start_date:2025-03-18 10:27:27.255050+00:00
[2025-03-18T10:27:27.328+0000] {logging_mixin.py:190} INFO - Dag name:kindle_store_etl_taskflow and current dag run status:running
[2025-03-18T10:27:27.328+0000] {taskinstance.py:732} INFO - ::endgroup::
[2025-03-18T10:40:53.867+0000] {log.py:232} WARNING - Error while downloading from https://cdn-lfs-us-1.hf.co/repos/e9/40/e940a8d106b2e3986d1f8b7626c5a3f4fced3c1f43b992d12b1d465b58efc824/acdaba5f1fb83805a2bf032ba3c7ddb83c695b03d6c41b785a81070d3b66a145?response-content-disposition=inline%3B+filename*%3DUTF-8%27%27meta_Kindle_Store.jsonl%3B+filename%3D%22meta_Kindle_Store.jsonl%22%3B&Expires=1742297250&Policy=eyJTdGF0ZW1lbnQiOlt7IkNvbmRpdGlvbiI6eyJEYXRlTGVzc1RoYW4iOnsiQVdTOkVwb2NoVGltZSI6MTc0MjI5NzI1MH19LCJSZXNvdXJjZSI6Imh0dHBzOi8vY2RuLWxmcy11cy0xLmhmLmNvL3JlcG9zL2U5LzQwL2U5NDBhOGQxMDZiMmUzOTg2ZDFmOGI3NjI2YzVhM2Y0ZmNlZDNjMWY0M2I5OTJkMTJiMWQ0NjViNThlZmM4MjQvYWNkYWJhNWYxZmI4MzgwNWEyYmYwMzJiYTNjN2RkYjgzYzY5NWIwM2Q2YzQxYjc4NWE4MTA3MGQzYjY2YTE0NT9yZXNwb25zZS1jb250ZW50LWRpc3Bvc2l0aW9uPSoifV19&Signature=cUrd65YLxbZOtfWJypM%7Ev6X85lNUMyamP-BS60Ue00dl0KoOMkWxAwzLt66nhcW1is0THVEUuk2jRBIFH%7EOj2xAaThWl00Sbeidqp1hjNDJOiCerKynU0lTzk4XBJj0xA1RvVlB2KNLCa13wkaSI-ovGj1xt%7EZB-GvjaxqrX2nJ6TSjaEOnLy9xMnfJ7KGD9ca62ym4r2ayifwgLKVTAF5sVO8BZ5mZ99Qm2uy3na99x9V2iavrBWI-vrjzKOd9ZJmvqNxChJdLLA3YHYmNgQ7%7EQffHGnbonD5isnRcadKU4vOVAH72XLT0ak5kYCbonIBnYw5qSgoO6ahzJzxBMWw__&Key-Pair-Id=K24J24Z295AEI9: HTTPSConnectionPool(host='cdn-lfs-us-1.hf.co', port=443): Read timed out.
Trying to resume download...
[2025-03-18T10:40:53.867+0000] {file_download.py:468} WARNING - Error while downloading from https://cdn-lfs-us-1.hf.co/repos/e9/40/e940a8d106b2e3986d1f8b7626c5a3f4fced3c1f43b992d12b1d465b58efc824/acdaba5f1fb83805a2bf032ba3c7ddb83c695b03d6c41b785a81070d3b66a145?response-content-disposition=inline%3B+filename*%3DUTF-8%27%27meta_Kindle_Store.jsonl%3B+filename%3D%22meta_Kindle_Store.jsonl%22%3B&Expires=1742297250&Policy=eyJTdGF0ZW1lbnQiOlt7IkNvbmRpdGlvbiI6eyJEYXRlTGVzc1RoYW4iOnsiQVdTOkVwb2NoVGltZSI6MTc0MjI5NzI1MH19LCJSZXNvdXJjZSI6Imh0dHBzOi8vY2RuLWxmcy11cy0xLmhmLmNvL3JlcG9zL2U5LzQwL2U5NDBhOGQxMDZiMmUzOTg2ZDFmOGI3NjI2YzVhM2Y0ZmNlZDNjMWY0M2I5OTJkMTJiMWQ0NjViNThlZmM4MjQvYWNkYWJhNWYxZmI4MzgwNWEyYmYwMzJiYTNjN2RkYjgzYzY5NWIwM2Q2YzQxYjc4NWE4MTA3MGQzYjY2YTE0NT9yZXNwb25zZS1jb250ZW50LWRpc3Bvc2l0aW9uPSoifV19&Signature=cUrd65YLxbZOtfWJypM%7Ev6X85lNUMyamP-BS60Ue00dl0KoOMkWxAwzLt66nhcW1is0THVEUuk2jRBIFH%7EOj2xAaThWl00Sbeidqp1hjNDJOiCerKynU0lTzk4XBJj0xA1RvVlB2KNLCa13wkaSI-ovGj1xt%7EZB-GvjaxqrX2nJ6TSjaEOnLy9xMnfJ7KGD9ca62ym4r2ayifwgLKVTAF5sVO8BZ5mZ99Qm2uy3na99x9V2iavrBWI-vrjzKOd9ZJmvqNxChJdLLA3YHYmNgQ7%7EQffHGnbonD5isnRcadKU4vOVAH72XLT0ak5kYCbonIBnYw5qSgoO6ahzJzxBMWw__&Key-Pair-Id=K24J24Z295AEI9: HTTPSConnectionPool(host='cdn-lfs-us-1.hf.co', port=443): Read timed out.
Trying to resume download...
[2025-03-18T10:40:54.874+0000] {taskinstance.py:3313} ERROR - Task failed with exception
Traceback (most recent call last):
  File "/home/airflow/.local/lib/python3.12/site-packages/urllib3/response.py", line 754, in _error_catcher
    yield
  File "/home/airflow/.local/lib/python3.12/site-packages/urllib3/response.py", line 879, in _raw_read
    data = self._fp_read(amt, read1=read1) if not fp_closed else b""
           ^^^^^^^^^^^^^^^^^^^^^^^^^^^^^^^
  File "/home/airflow/.local/lib/python3.12/site-packages/urllib3/response.py", line 862, in _fp_read
    return self._fp.read(amt) if amt is not None else self._fp.read()
           ^^^^^^^^^^^^^^^^^^
  File "/usr/local/lib/python3.12/http/client.py", line 479, in read
    s = self.fp.read(amt)
        ^^^^^^^^^^^^^^^^^
  File "/usr/local/lib/python3.12/socket.py", line 720, in readinto
    return self._sock.recv_into(b)
           ^^^^^^^^^^^^^^^^^^^^^^^
  File "/usr/local/lib/python3.12/ssl.py", line 1251, in recv_into
    return self.read(nbytes, buffer)
           ^^^^^^^^^^^^^^^^^^^^^^^^^
  File "/usr/local/lib/python3.12/ssl.py", line 1103, in read
    return self._sslobj.read(len, buffer)
           ^^^^^^^^^^^^^^^^^^^^^^^^^^^^^^
TimeoutError: The read operation timed out

The above exception was the direct cause of the following exception:

Traceback (most recent call last):
  File "/home/airflow/.local/lib/python3.12/site-packages/requests/models.py", line 820, in generate
    yield from self.raw.stream(chunk_size, decode_content=True)
  File "/home/airflow/.local/lib/python3.12/site-packages/urllib3/response.py", line 1066, in stream
    data = self.read(amt=amt, decode_content=decode_content)
           ^^^^^^^^^^^^^^^^^^^^^^^^^^^^^^^^^^^^^^^^^^^^^^^^^
  File "/home/airflow/.local/lib/python3.12/site-packages/urllib3/response.py", line 955, in read
    data = self._raw_read(amt)
           ^^^^^^^^^^^^^^^^^^^
  File "/home/airflow/.local/lib/python3.12/site-packages/urllib3/response.py", line 878, in _raw_read
    with self._error_catcher():
         ^^^^^^^^^^^^^^^^^^^^^
  File "/usr/local/lib/python3.12/contextlib.py", line 158, in __exit__
    self.gen.throw(value)
  File "/home/airflow/.local/lib/python3.12/site-packages/urllib3/response.py", line 759, in _error_catcher
    raise ReadTimeoutError(self._pool, None, "Read timed out.") from e  # type: ignore[arg-type]
    ^^^^^^^^^^^^^^^^^^^^^^^^^^^^^^^^^^^^^^^^^^^^^^^^^^^^^^^^^^^^^^^^^^
urllib3.exceptions.ReadTimeoutError: HTTPSConnectionPool(host='cdn-lfs-us-1.hf.co', port=443): Read timed out.

During handling of the above exception, another exception occurred:

Traceback (most recent call last):
  File "/home/airflow/.local/lib/python3.12/site-packages/huggingface_hub/file_download.py", line 454, in http_get
    for chunk in r.iter_content(chunk_size=constants.DOWNLOAD_CHUNK_SIZE):
                 ^^^^^^^^^^^^^^^^^^^^^^^^^^^^^^^^^^^^^^^^^^^^^^^^^^^^^^^^
  File "/home/airflow/.local/lib/python3.12/site-packages/requests/models.py", line 826, in generate
    raise ConnectionError(e)
requests.exceptions.ConnectionError: HTTPSConnectionPool(host='cdn-lfs-us-1.hf.co', port=443): Read timed out.

During handling of the above exception, another exception occurred:

Traceback (most recent call last):
  File "/home/airflow/.local/lib/python3.12/site-packages/urllib3/connection.py", line 198, in _new_conn
    sock = connection.create_connection(
           ^^^^^^^^^^^^^^^^^^^^^^^^^^^^^
  File "/home/airflow/.local/lib/python3.12/site-packages/urllib3/util/connection.py", line 60, in create_connection
    for res in socket.getaddrinfo(host, port, family, socket.SOCK_STREAM):
               ^^^^^^^^^^^^^^^^^^^^^^^^^^^^^^^^^^^^^^^^^^^^^^^^^^^^^^^^^^
  File "/usr/local/lib/python3.12/socket.py", line 978, in getaddrinfo
    for res in _socket.getaddrinfo(host, port, family, type, proto, flags):
               ^^^^^^^^^^^^^^^^^^^^^^^^^^^^^^^^^^^^^^^^^^^^^^^^^^^^^^^^^^^
socket.gaierror: [Errno -2] Name or service not known

The above exception was the direct cause of the following exception:

Traceback (most recent call last):
  File "/home/airflow/.local/lib/python3.12/site-packages/urllib3/connectionpool.py", line 787, in urlopen
    response = self._make_request(
               ^^^^^^^^^^^^^^^^^^^
  File "/home/airflow/.local/lib/python3.12/site-packages/urllib3/connectionpool.py", line 488, in _make_request
    raise new_e
  File "/home/airflow/.local/lib/python3.12/site-packages/urllib3/connectionpool.py", line 464, in _make_request
    self._validate_conn(conn)
  File "/home/airflow/.local/lib/python3.12/site-packages/urllib3/connectionpool.py", line 1093, in _validate_conn
    conn.connect()
  File "/home/airflow/.local/lib/python3.12/site-packages/urllib3/connection.py", line 704, in connect
    self.sock = sock = self._new_conn()
                       ^^^^^^^^^^^^^^^^
  File "/home/airflow/.local/lib/python3.12/site-packages/urllib3/connection.py", line 205, in _new_conn
    raise NameResolutionError(self.host, self, e) from e
urllib3.exceptions.NameResolutionError: <urllib3.connection.HTTPSConnection object at 0xffff3f3432c0>: Failed to resolve 'cdn-lfs-us-1.hf.co' ([Errno -2] Name or service not known)

The above exception was the direct cause of the following exception:

Traceback (most recent call last):
  File "/home/airflow/.local/lib/python3.12/site-packages/requests/adapters.py", line 667, in send
    resp = conn.urlopen(
           ^^^^^^^^^^^^^
  File "/home/airflow/.local/lib/python3.12/site-packages/urllib3/connectionpool.py", line 841, in urlopen
    retries = retries.increment(
              ^^^^^^^^^^^^^^^^^^
  File "/home/airflow/.local/lib/python3.12/site-packages/urllib3/util/retry.py", line 519, in increment
    raise MaxRetryError(_pool, url, reason) from reason  # type: ignore[arg-type]
    ^^^^^^^^^^^^^^^^^^^^^^^^^^^^^^^^^^^^^^^^^^^^^^^^^^^
urllib3.exceptions.MaxRetryError: HTTPSConnectionPool(host='cdn-lfs-us-1.hf.co', port=443): Max retries exceeded with url: /repos/e9/40/e940a8d106b2e3986d1f8b7626c5a3f4fced3c1f43b992d12b1d465b58efc824/acdaba5f1fb83805a2bf032ba3c7ddb83c695b03d6c41b785a81070d3b66a145?response-content-disposition=inline%3B+filename*%3DUTF-8%27%27meta_Kindle_Store.jsonl%3B+filename%3D%22meta_Kindle_Store.jsonl%22%3B&Expires=1742297250&Policy=eyJTdGF0ZW1lbnQiOlt7IkNvbmRpdGlvbiI6eyJEYXRlTGVzc1RoYW4iOnsiQVdTOkVwb2NoVGltZSI6MTc0MjI5NzI1MH19LCJSZXNvdXJjZSI6Imh0dHBzOi8vY2RuLWxmcy11cy0xLmhmLmNvL3JlcG9zL2U5LzQwL2U5NDBhOGQxMDZiMmUzOTg2ZDFmOGI3NjI2YzVhM2Y0ZmNlZDNjMWY0M2I5OTJkMTJiMWQ0NjViNThlZmM4MjQvYWNkYWJhNWYxZmI4MzgwNWEyYmYwMzJiYTNjN2RkYjgzYzY5NWIwM2Q2YzQxYjc4NWE4MTA3MGQzYjY2YTE0NT9yZXNwb25zZS1jb250ZW50LWRpc3Bvc2l0aW9uPSoifV19&Signature=cUrd65YLxbZOtfWJypM~v6X85lNUMyamP-BS60Ue00dl0KoOMkWxAwzLt66nhcW1is0THVEUuk2jRBIFH~Oj2xAaThWl00Sbeidqp1hjNDJOiCerKynU0lTzk4XBJj0xA1RvVlB2KNLCa13wkaSI-ovGj1xt~ZB-GvjaxqrX2nJ6TSjaEOnLy9xMnfJ7KGD9ca62ym4r2ayifwgLKVTAF5sVO8BZ5mZ99Qm2uy3na99x9V2iavrBWI-vrjzKOd9ZJmvqNxChJdLLA3YHYmNgQ7~QffHGnbonD5isnRcadKU4vOVAH72XLT0ak5kYCbonIBnYw5qSgoO6ahzJzxBMWw__&Key-Pair-Id=K24J24Z295AEI9 (Caused by NameResolutionError("<urllib3.connection.HTTPSConnection object at 0xffff3f3432c0>: Failed to resolve 'cdn-lfs-us-1.hf.co' ([Errno -2] Name or service not known)"))

During handling of the above exception, another exception occurred:

Traceback (most recent call last):
  File "/home/airflow/.local/lib/python3.12/site-packages/airflow/models/taskinstance.py", line 768, in _execute_task
    result = _execute_callable(context=context, **execute_callable_kwargs)
             ^^^^^^^^^^^^^^^^^^^^^^^^^^^^^^^^^^^^^^^^^^^^^^^^^^^^^^^^^^^^^
  File "/home/airflow/.local/lib/python3.12/site-packages/airflow/models/taskinstance.py", line 734, in _execute_callable
    return ExecutionCallableRunner(
           ^^^^^^^^^^^^^^^^^^^^^^^^
  File "/home/airflow/.local/lib/python3.12/site-packages/airflow/utils/operator_helpers.py", line 252, in run
    return self.func(*args, **kwargs)
           ^^^^^^^^^^^^^^^^^^^^^^^^^^
  File "/home/airflow/.local/lib/python3.12/site-packages/airflow/models/baseoperator.py", line 424, in wrapper
    return func(self, *args, **kwargs)
           ^^^^^^^^^^^^^^^^^^^^^^^^^^^
  File "/home/airflow/.local/lib/python3.12/site-packages/airflow/decorators/base.py", line 266, in execute
    return_value = super().execute(context)
                   ^^^^^^^^^^^^^^^^^^^^^^^^
  File "/home/airflow/.local/lib/python3.12/site-packages/airflow/models/baseoperator.py", line 424, in wrapper
    return func(self, *args, **kwargs)
           ^^^^^^^^^^^^^^^^^^^^^^^^^^^
  File "/home/airflow/.local/lib/python3.12/site-packages/airflow/operators/python.py", line 238, in execute
    return_value = self.execute_callable()
                   ^^^^^^^^^^^^^^^^^^^^^^^
  File "/home/airflow/.local/lib/python3.12/site-packages/airflow/operators/python.py", line 256, in execute_callable
    return runner.run(*self.op_args, **self.op_kwargs)
           ^^^^^^^^^^^^^^^^^^^^^^^^^^^^^^^^^^^^^^^^^^^
  File "/home/airflow/.local/lib/python3.12/site-packages/airflow/utils/operator_helpers.py", line 252, in run
    return self.func(*args, **kwargs)
           ^^^^^^^^^^^^^^^^^^^^^^^^^^
  File "/opt/airflow/dags/etl.py", line 59, in extract_book_data
    metadata_dataset = load_dataset("McAuley-Lab/Amazon-Reviews-2023", "raw_meta_Kindle_Store", trust_remote_code=True,num_proc=16,split = 'full')
                       ^^^^^^^^^^^^^^^^^^^^^^^^^^^^^^^^^^^^^^^^^^^^^^^^^^^^^^^^^^^^^^^^^^^^^^^^^^^^^^^^^^^^^^^^^^^^^^^^^^^^^^^^^^^^^^^^^^^^^^^^^^^
  File "/home/airflow/.local/lib/python3.12/site-packages/datasets/load.py", line 2083, in load_dataset
    builder_instance.download_and_prepare(
  File "/home/airflow/.local/lib/python3.12/site-packages/datasets/builder.py", line 925, in download_and_prepare
    self._download_and_prepare(
  File "/home/airflow/.local/lib/python3.12/site-packages/datasets/builder.py", line 1649, in _download_and_prepare
    super()._download_and_prepare(
  File "/home/airflow/.local/lib/python3.12/site-packages/datasets/builder.py", line 979, in _download_and_prepare
    split_generators = self._split_generators(dl_manager, **split_generators_kwargs)
                       ^^^^^^^^^^^^^^^^^^^^^^^^^^^^^^^^^^^^^^^^^^^^^^^^^^^^^^^^^^^^^
  File "/home/airflow/.cache/huggingface/modules/datasets_modules/datasets/McAuley-Lab--Amazon-Reviews-2023/16b76e0823d73bb8cff1e9c5e3e37dbc46ae3daee380417ae141f5e67d3ea8e8/Amazon-Reviews-2023.py", line 509, in _split_generators
    dl_dir = dl_manager.download_and_extract(self.config.data_dir)
             ^^^^^^^^^^^^^^^^^^^^^^^^^^^^^^^^^^^^^^^^^^^^^^^^^^^^^
  File "/home/airflow/.local/lib/python3.12/site-packages/datasets/download/download_manager.py", line 326, in download_and_extract
    return self.extract(self.download(url_or_urls))
                        ^^^^^^^^^^^^^^^^^^^^^^^^^^
  File "/home/airflow/.local/lib/python3.12/site-packages/datasets/download/download_manager.py", line 159, in download
    downloaded_path_or_paths = map_nested(
                               ^^^^^^^^^^^
  File "/home/airflow/.local/lib/python3.12/site-packages/datasets/utils/py_utils.py", line 486, in map_nested
    mapped = function(data_struct)
             ^^^^^^^^^^^^^^^^^^^^^
  File "/home/airflow/.local/lib/python3.12/site-packages/datasets/download/download_manager.py", line 220, in _download_batched
    self._download_single(url_or_filename, download_config=download_config)
  File "/home/airflow/.local/lib/python3.12/site-packages/datasets/download/download_manager.py", line 229, in _download_single
    out = cached_path(url_or_filename, download_config=download_config)
          ^^^^^^^^^^^^^^^^^^^^^^^^^^^^^^^^^^^^^^^^^^^^^^^^^^^^^^^^^^^^^
  File "/home/airflow/.local/lib/python3.12/site-packages/datasets/utils/file_utils.py", line 189, in cached_path
    ).hf_hub_download(
      ^^^^^^^^^^^^^^^^
  File "/home/airflow/.local/lib/python3.12/site-packages/huggingface_hub/utils/_validators.py", line 114, in _inner_fn
    return fn(*args, **kwargs)
           ^^^^^^^^^^^^^^^^^^^
  File "/home/airflow/.local/lib/python3.12/site-packages/huggingface_hub/hf_api.py", line 5248, in hf_hub_download
    return hf_hub_download(
           ^^^^^^^^^^^^^^^^
  File "/home/airflow/.local/lib/python3.12/site-packages/huggingface_hub/utils/_validators.py", line 114, in _inner_fn
    return fn(*args, **kwargs)
           ^^^^^^^^^^^^^^^^^^^
  File "/home/airflow/.local/lib/python3.12/site-packages/huggingface_hub/file_download.py", line 862, in hf_hub_download
    return _hf_hub_download_to_cache_dir(
           ^^^^^^^^^^^^^^^^^^^^^^^^^^^^^^
  File "/home/airflow/.local/lib/python3.12/site-packages/huggingface_hub/file_download.py", line 1011, in _hf_hub_download_to_cache_dir
    _download_to_tmp_and_move(
  File "/home/airflow/.local/lib/python3.12/site-packages/huggingface_hub/file_download.py", line 1547, in _download_to_tmp_and_move
    http_get(
  File "/home/airflow/.local/lib/python3.12/site-packages/huggingface_hub/file_download.py", line 471, in http_get
    return http_get(
           ^^^^^^^^^
  File "/home/airflow/.local/lib/python3.12/site-packages/huggingface_hub/file_download.py", line 371, in http_get
    r = _request_wrapper(
        ^^^^^^^^^^^^^^^^^
  File "/home/airflow/.local/lib/python3.12/site-packages/huggingface_hub/file_download.py", line 303, in _request_wrapper
    response = get_session().request(method=method, url=url, **params)
               ^^^^^^^^^^^^^^^^^^^^^^^^^^^^^^^^^^^^^^^^^^^^^^^^^^^^^^^
  File "/home/airflow/.local/lib/python3.12/site-packages/requests/sessions.py", line 589, in request
    resp = self.send(prep, **send_kwargs)
           ^^^^^^^^^^^^^^^^^^^^^^^^^^^^^^
  File "/home/airflow/.local/lib/python3.12/site-packages/requests/sessions.py", line 703, in send
    r = adapter.send(request, **kwargs)
        ^^^^^^^^^^^^^^^^^^^^^^^^^^^^^^^
  File "/home/airflow/.local/lib/python3.12/site-packages/huggingface_hub/utils/_http.py", line 96, in send
    return super().send(request, *args, **kwargs)
           ^^^^^^^^^^^^^^^^^^^^^^^^^^^^^^^^^^^^^^
  File "/home/airflow/.local/lib/python3.12/site-packages/requests/adapters.py", line 700, in send
    raise ConnectionError(e, request=request)
requests.exceptions.ConnectionError: (MaxRetryError('HTTPSConnectionPool(host=\'cdn-lfs-us-1.hf.co\', port=443): Max retries exceeded with url: /repos/e9/40/e940a8d106b2e3986d1f8b7626c5a3f4fced3c1f43b992d12b1d465b58efc824/acdaba5f1fb83805a2bf032ba3c7ddb83c695b03d6c41b785a81070d3b66a145?response-content-disposition=inline%3B+filename*%3DUTF-8%27%27meta_Kindle_Store.jsonl%3B+filename%3D%22meta_Kindle_Store.jsonl%22%3B&Expires=1742297250&Policy=eyJTdGF0ZW1lbnQiOlt7IkNvbmRpdGlvbiI6eyJEYXRlTGVzc1RoYW4iOnsiQVdTOkVwb2NoVGltZSI6MTc0MjI5NzI1MH19LCJSZXNvdXJjZSI6Imh0dHBzOi8vY2RuLWxmcy11cy0xLmhmLmNvL3JlcG9zL2U5LzQwL2U5NDBhOGQxMDZiMmUzOTg2ZDFmOGI3NjI2YzVhM2Y0ZmNlZDNjMWY0M2I5OTJkMTJiMWQ0NjViNThlZmM4MjQvYWNkYWJhNWYxZmI4MzgwNWEyYmYwMzJiYTNjN2RkYjgzYzY5NWIwM2Q2YzQxYjc4NWE4MTA3MGQzYjY2YTE0NT9yZXNwb25zZS1jb250ZW50LWRpc3Bvc2l0aW9uPSoifV19&Signature=cUrd65YLxbZOtfWJypM~v6X85lNUMyamP-BS60Ue00dl0KoOMkWxAwzLt66nhcW1is0THVEUuk2jRBIFH~Oj2xAaThWl00Sbeidqp1hjNDJOiCerKynU0lTzk4XBJj0xA1RvVlB2KNLCa13wkaSI-ovGj1xt~ZB-GvjaxqrX2nJ6TSjaEOnLy9xMnfJ7KGD9ca62ym4r2ayifwgLKVTAF5sVO8BZ5mZ99Qm2uy3na99x9V2iavrBWI-vrjzKOd9ZJmvqNxChJdLLA3YHYmNgQ7~QffHGnbonD5isnRcadKU4vOVAH72XLT0ak5kYCbonIBnYw5qSgoO6ahzJzxBMWw__&Key-Pair-Id=K24J24Z295AEI9 (Caused by NameResolutionError("<urllib3.connection.HTTPSConnection object at 0xffff3f3432c0>: Failed to resolve \'cdn-lfs-us-1.hf.co\' ([Errno -2] Name or service not known)"))'), '(Request ID: 3f32ae61-0f86-436e-8993-db4af34bd365)')
[2025-03-18T10:40:54.891+0000] {logging_mixin.py:190} INFO - Task instance in failure state
[2025-03-18T10:40:54.891+0000] {logging_mixin.py:190} INFO - Task start:2025-03-18 10:27:27.255050+00:00 end:2025-03-18 10:40:54.891431+00:00 duration:807.636381
[2025-03-18T10:40:54.892+0000] {logging_mixin.py:190} INFO - Task:<Task(_PythonDecoratedOperator): extract_book_data> dag:<DAG: kindle_store_etl_taskflow> dagrun:<DagRun kindle_store_etl_taskflow @ 2025-03-18 10:27:25.081541+00:00: manual__2025-03-18T10:27:25.081541+00:00, state:running, queued_at: 2025-03-18 10:27:25.092536+00:00. externally triggered: True>
[2025-03-18T10:40:54.892+0000] {logging_mixin.py:190} INFO - Failure caused by (MaxRetryError('HTTPSConnectionPool(host=\'cdn-lfs-us-1.hf.co\', port=443): Max retries exceeded with url: /repos/e9/40/e940a8d106b2e3986d1f8b7626c5a3f4fced3c1f43b992d12b1d465b58efc824/acdaba5f1fb83805a2bf032ba3c7ddb83c695b03d6c41b785a81070d3b66a145?response-content-disposition=inline%3B+filename*%3DUTF-8%27%27meta_Kindle_Store.jsonl%3B+filename%3D%22meta_Kindle_Store.jsonl%22%3B&Expires=1742297250&Policy=eyJTdGF0ZW1lbnQiOlt7IkNvbmRpdGlvbiI6eyJEYXRlTGVzc1RoYW4iOnsiQVdTOkVwb2NoVGltZSI6MTc0MjI5NzI1MH19LCJSZXNvdXJjZSI6Imh0dHBzOi8vY2RuLWxmcy11cy0xLmhmLmNvL3JlcG9zL2U5LzQwL2U5NDBhOGQxMDZiMmUzOTg2ZDFmOGI3NjI2YzVhM2Y0ZmNlZDNjMWY0M2I5OTJkMTJiMWQ0NjViNThlZmM4MjQvYWNkYWJhNWYxZmI4MzgwNWEyYmYwMzJiYTNjN2RkYjgzYzY5NWIwM2Q2YzQxYjc4NWE4MTA3MGQzYjY2YTE0NT9yZXNwb25zZS1jb250ZW50LWRpc3Bvc2l0aW9uPSoifV19&Signature=cUrd65YLxbZOtfWJypM~v6X85lNUMyamP-BS60Ue00dl0KoOMkWxAwzLt66nhcW1is0THVEUuk2jRBIFH~Oj2xAaThWl00Sbeidqp1hjNDJOiCerKynU0lTzk4XBJj0xA1RvVlB2KNLCa13wkaSI-ovGj1xt~ZB-GvjaxqrX2nJ6TSjaEOnLy9xMnfJ7KGD9ca62ym4r2ayifwgLKVTAF5sVO8BZ5mZ99Qm2uy3na99x9V2iavrBWI-vrjzKOd9ZJmvqNxChJdLLA3YHYmNgQ7~QffHGnbonD5isnRcadKU4vOVAH72XLT0ak5kYCbonIBnYw5qSgoO6ahzJzxBMWw__&Key-Pair-Id=K24J24Z295AEI9 (Caused by NameResolutionError("<urllib3.connection.HTTPSConnection object at 0xffff3f3432c0>: Failed to resolve \'cdn-lfs-us-1.hf.co\' ([Errno -2] Name or service not known)"))'), '(Request ID: 3f32ae61-0f86-436e-8993-db4af34bd365)')
[2025-03-18T10:40:54.892+0000] {taskinstance.py:1226} INFO - Marking task as FAILED. dag_id=kindle_store_etl_taskflow, task_id=extract_book_data, run_id=manual__2025-03-18T10:27:25.081541+00:00, execution_date=20250318T102725, start_date=20250318T102727, end_date=20250318T104054
[2025-03-18T10:40:54.904+0000] {taskinstance.py:341} INFO - ::group::Post task execution logs
[2025-03-18T10:40:54.905+0000] {standard_task_runner.py:124} ERROR - Failed to execute job 26 for task extract_book_data ((MaxRetryError('HTTPSConnectionPool(host=\'cdn-lfs-us-1.hf.co\', port=443): Max retries exceeded with url: /repos/e9/40/e940a8d106b2e3986d1f8b7626c5a3f4fced3c1f43b992d12b1d465b58efc824/acdaba5f1fb83805a2bf032ba3c7ddb83c695b03d6c41b785a81070d3b66a145?response-content-disposition=inline%3B+filename*%3DUTF-8%27%27meta_Kindle_Store.jsonl%3B+filename%3D%22meta_Kindle_Store.jsonl%22%3B&Expires=1742297250&Policy=eyJTdGF0ZW1lbnQiOlt7IkNvbmRpdGlvbiI6eyJEYXRlTGVzc1RoYW4iOnsiQVdTOkVwb2NoVGltZSI6MTc0MjI5NzI1MH19LCJSZXNvdXJjZSI6Imh0dHBzOi8vY2RuLWxmcy11cy0xLmhmLmNvL3JlcG9zL2U5LzQwL2U5NDBhOGQxMDZiMmUzOTg2ZDFmOGI3NjI2YzVhM2Y0ZmNlZDNjMWY0M2I5OTJkMTJiMWQ0NjViNThlZmM4MjQvYWNkYWJhNWYxZmI4MzgwNWEyYmYwMzJiYTNjN2RkYjgzYzY5NWIwM2Q2YzQxYjc4NWE4MTA3MGQzYjY2YTE0NT9yZXNwb25zZS1jb250ZW50LWRpc3Bvc2l0aW9uPSoifV19&Signature=cUrd65YLxbZOtfWJypM~v6X85lNUMyamP-BS60Ue00dl0KoOMkWxAwzLt66nhcW1is0THVEUuk2jRBIFH~Oj2xAaThWl00Sbeidqp1hjNDJOiCerKynU0lTzk4XBJj0xA1RvVlB2KNLCa13wkaSI-ovGj1xt~ZB-GvjaxqrX2nJ6TSjaEOnLy9xMnfJ7KGD9ca62ym4r2ayifwgLKVTAF5sVO8BZ5mZ99Qm2uy3na99x9V2iavrBWI-vrjzKOd9ZJmvqNxChJdLLA3YHYmNgQ7~QffHGnbonD5isnRcadKU4vOVAH72XLT0ak5kYCbonIBnYw5qSgoO6ahzJzxBMWw__&Key-Pair-Id=K24J24Z295AEI9 (Caused by NameResolutionError("<urllib3.connection.HTTPSConnection object at 0xffff3f3432c0>: Failed to resolve \'cdn-lfs-us-1.hf.co\' ([Errno -2] Name or service not known)"))'), '(Request ID: 3f32ae61-0f86-436e-8993-db4af34bd365)'); 179)
Traceback (most recent call last):
  File "/home/airflow/.local/lib/python3.12/site-packages/urllib3/response.py", line 754, in _error_catcher
    yield
  File "/home/airflow/.local/lib/python3.12/site-packages/urllib3/response.py", line 879, in _raw_read
    data = self._fp_read(amt, read1=read1) if not fp_closed else b""
           ^^^^^^^^^^^^^^^^^^^^^^^^^^^^^^^
  File "/home/airflow/.local/lib/python3.12/site-packages/urllib3/response.py", line 862, in _fp_read
    return self._fp.read(amt) if amt is not None else self._fp.read()
           ^^^^^^^^^^^^^^^^^^
  File "/usr/local/lib/python3.12/http/client.py", line 479, in read
    s = self.fp.read(amt)
        ^^^^^^^^^^^^^^^^^
  File "/usr/local/lib/python3.12/socket.py", line 720, in readinto
    return self._sock.recv_into(b)
           ^^^^^^^^^^^^^^^^^^^^^^^
  File "/usr/local/lib/python3.12/ssl.py", line 1251, in recv_into
    return self.read(nbytes, buffer)
           ^^^^^^^^^^^^^^^^^^^^^^^^^
  File "/usr/local/lib/python3.12/ssl.py", line 1103, in read
    return self._sslobj.read(len, buffer)
           ^^^^^^^^^^^^^^^^^^^^^^^^^^^^^^
TimeoutError: The read operation timed out

The above exception was the direct cause of the following exception:

Traceback (most recent call last):
  File "/home/airflow/.local/lib/python3.12/site-packages/requests/models.py", line 820, in generate
    yield from self.raw.stream(chunk_size, decode_content=True)
  File "/home/airflow/.local/lib/python3.12/site-packages/urllib3/response.py", line 1066, in stream
    data = self.read(amt=amt, decode_content=decode_content)
           ^^^^^^^^^^^^^^^^^^^^^^^^^^^^^^^^^^^^^^^^^^^^^^^^^
  File "/home/airflow/.local/lib/python3.12/site-packages/urllib3/response.py", line 955, in read
    data = self._raw_read(amt)
           ^^^^^^^^^^^^^^^^^^^
  File "/home/airflow/.local/lib/python3.12/site-packages/urllib3/response.py", line 878, in _raw_read
    with self._error_catcher():
         ^^^^^^^^^^^^^^^^^^^^^
  File "/usr/local/lib/python3.12/contextlib.py", line 158, in __exit__
    self.gen.throw(value)
  File "/home/airflow/.local/lib/python3.12/site-packages/urllib3/response.py", line 759, in _error_catcher
    raise ReadTimeoutError(self._pool, None, "Read timed out.") from e  # type: ignore[arg-type]
    ^^^^^^^^^^^^^^^^^^^^^^^^^^^^^^^^^^^^^^^^^^^^^^^^^^^^^^^^^^^^^^^^^^
urllib3.exceptions.ReadTimeoutError: HTTPSConnectionPool(host='cdn-lfs-us-1.hf.co', port=443): Read timed out.

During handling of the above exception, another exception occurred:

Traceback (most recent call last):
  File "/home/airflow/.local/lib/python3.12/site-packages/huggingface_hub/file_download.py", line 454, in http_get
    for chunk in r.iter_content(chunk_size=constants.DOWNLOAD_CHUNK_SIZE):
                 ^^^^^^^^^^^^^^^^^^^^^^^^^^^^^^^^^^^^^^^^^^^^^^^^^^^^^^^^
  File "/home/airflow/.local/lib/python3.12/site-packages/requests/models.py", line 826, in generate
    raise ConnectionError(e)
requests.exceptions.ConnectionError: HTTPSConnectionPool(host='cdn-lfs-us-1.hf.co', port=443): Read timed out.

During handling of the above exception, another exception occurred:

Traceback (most recent call last):
  File "/home/airflow/.local/lib/python3.12/site-packages/urllib3/connection.py", line 198, in _new_conn
    sock = connection.create_connection(
           ^^^^^^^^^^^^^^^^^^^^^^^^^^^^^
  File "/home/airflow/.local/lib/python3.12/site-packages/urllib3/util/connection.py", line 60, in create_connection
    for res in socket.getaddrinfo(host, port, family, socket.SOCK_STREAM):
               ^^^^^^^^^^^^^^^^^^^^^^^^^^^^^^^^^^^^^^^^^^^^^^^^^^^^^^^^^^
  File "/usr/local/lib/python3.12/socket.py", line 978, in getaddrinfo
    for res in _socket.getaddrinfo(host, port, family, type, proto, flags):
               ^^^^^^^^^^^^^^^^^^^^^^^^^^^^^^^^^^^^^^^^^^^^^^^^^^^^^^^^^^^
socket.gaierror: [Errno -2] Name or service not known

The above exception was the direct cause of the following exception:

Traceback (most recent call last):
  File "/home/airflow/.local/lib/python3.12/site-packages/urllib3/connectionpool.py", line 787, in urlopen
    response = self._make_request(
               ^^^^^^^^^^^^^^^^^^^
  File "/home/airflow/.local/lib/python3.12/site-packages/urllib3/connectionpool.py", line 488, in _make_request
    raise new_e
  File "/home/airflow/.local/lib/python3.12/site-packages/urllib3/connectionpool.py", line 464, in _make_request
    self._validate_conn(conn)
  File "/home/airflow/.local/lib/python3.12/site-packages/urllib3/connectionpool.py", line 1093, in _validate_conn
    conn.connect()
  File "/home/airflow/.local/lib/python3.12/site-packages/urllib3/connection.py", line 704, in connect
    self.sock = sock = self._new_conn()
                       ^^^^^^^^^^^^^^^^
  File "/home/airflow/.local/lib/python3.12/site-packages/urllib3/connection.py", line 205, in _new_conn
    raise NameResolutionError(self.host, self, e) from e
urllib3.exceptions.NameResolutionError: <urllib3.connection.HTTPSConnection object at 0xffff3f3432c0>: Failed to resolve 'cdn-lfs-us-1.hf.co' ([Errno -2] Name or service not known)

The above exception was the direct cause of the following exception:

Traceback (most recent call last):
  File "/home/airflow/.local/lib/python3.12/site-packages/requests/adapters.py", line 667, in send
    resp = conn.urlopen(
           ^^^^^^^^^^^^^
  File "/home/airflow/.local/lib/python3.12/site-packages/urllib3/connectionpool.py", line 841, in urlopen
    retries = retries.increment(
              ^^^^^^^^^^^^^^^^^^
  File "/home/airflow/.local/lib/python3.12/site-packages/urllib3/util/retry.py", line 519, in increment
    raise MaxRetryError(_pool, url, reason) from reason  # type: ignore[arg-type]
    ^^^^^^^^^^^^^^^^^^^^^^^^^^^^^^^^^^^^^^^^^^^^^^^^^^^
urllib3.exceptions.MaxRetryError: HTTPSConnectionPool(host='cdn-lfs-us-1.hf.co', port=443): Max retries exceeded with url: /repos/e9/40/e940a8d106b2e3986d1f8b7626c5a3f4fced3c1f43b992d12b1d465b58efc824/acdaba5f1fb83805a2bf032ba3c7ddb83c695b03d6c41b785a81070d3b66a145?response-content-disposition=inline%3B+filename*%3DUTF-8%27%27meta_Kindle_Store.jsonl%3B+filename%3D%22meta_Kindle_Store.jsonl%22%3B&Expires=1742297250&Policy=eyJTdGF0ZW1lbnQiOlt7IkNvbmRpdGlvbiI6eyJEYXRlTGVzc1RoYW4iOnsiQVdTOkVwb2NoVGltZSI6MTc0MjI5NzI1MH19LCJSZXNvdXJjZSI6Imh0dHBzOi8vY2RuLWxmcy11cy0xLmhmLmNvL3JlcG9zL2U5LzQwL2U5NDBhOGQxMDZiMmUzOTg2ZDFmOGI3NjI2YzVhM2Y0ZmNlZDNjMWY0M2I5OTJkMTJiMWQ0NjViNThlZmM4MjQvYWNkYWJhNWYxZmI4MzgwNWEyYmYwMzJiYTNjN2RkYjgzYzY5NWIwM2Q2YzQxYjc4NWE4MTA3MGQzYjY2YTE0NT9yZXNwb25zZS1jb250ZW50LWRpc3Bvc2l0aW9uPSoifV19&Signature=cUrd65YLxbZOtfWJypM~v6X85lNUMyamP-BS60Ue00dl0KoOMkWxAwzLt66nhcW1is0THVEUuk2jRBIFH~Oj2xAaThWl00Sbeidqp1hjNDJOiCerKynU0lTzk4XBJj0xA1RvVlB2KNLCa13wkaSI-ovGj1xt~ZB-GvjaxqrX2nJ6TSjaEOnLy9xMnfJ7KGD9ca62ym4r2ayifwgLKVTAF5sVO8BZ5mZ99Qm2uy3na99x9V2iavrBWI-vrjzKOd9ZJmvqNxChJdLLA3YHYmNgQ7~QffHGnbonD5isnRcadKU4vOVAH72XLT0ak5kYCbonIBnYw5qSgoO6ahzJzxBMWw__&Key-Pair-Id=K24J24Z295AEI9 (Caused by NameResolutionError("<urllib3.connection.HTTPSConnection object at 0xffff3f3432c0>: Failed to resolve 'cdn-lfs-us-1.hf.co' ([Errno -2] Name or service not known)"))

During handling of the above exception, another exception occurred:

Traceback (most recent call last):
  File "/home/airflow/.local/lib/python3.12/site-packages/airflow/task/task_runner/standard_task_runner.py", line 117, in _start_by_fork
    ret = args.func(args, dag=self.dag)
          ^^^^^^^^^^^^^^^^^^^^^^^^^^^^^
  File "/home/airflow/.local/lib/python3.12/site-packages/airflow/cli/cli_config.py", line 49, in command
    return func(*args, **kwargs)
           ^^^^^^^^^^^^^^^^^^^^^
  File "/home/airflow/.local/lib/python3.12/site-packages/airflow/utils/cli.py", line 116, in wrapper
    return f(*args, **kwargs)
           ^^^^^^^^^^^^^^^^^^
  File "/home/airflow/.local/lib/python3.12/site-packages/airflow/cli/commands/task_command.py", line 483, in task_run
    task_return_code = _run_task_by_selected_method(args, _dag, ti)
                       ^^^^^^^^^^^^^^^^^^^^^^^^^^^^^^^^^^^^^^^^^^^^
  File "/home/airflow/.local/lib/python3.12/site-packages/airflow/cli/commands/task_command.py", line 256, in _run_task_by_selected_method
    return _run_raw_task(args, ti)
           ^^^^^^^^^^^^^^^^^^^^^^^
  File "/home/airflow/.local/lib/python3.12/site-packages/airflow/cli/commands/task_command.py", line 341, in _run_raw_task
    return ti._run_raw_task(
           ^^^^^^^^^^^^^^^^^
  File "/home/airflow/.local/lib/python3.12/site-packages/airflow/utils/session.py", line 97, in wrapper
    return func(*args, session=session, **kwargs)
           ^^^^^^^^^^^^^^^^^^^^^^^^^^^^^^^^^^^^^^
  File "/home/airflow/.local/lib/python3.12/site-packages/airflow/models/taskinstance.py", line 3006, in _run_raw_task
    return _run_raw_task(
           ^^^^^^^^^^^^^^
  File "/home/airflow/.local/lib/python3.12/site-packages/airflow/models/taskinstance.py", line 274, in _run_raw_task
    TaskInstance._execute_task_with_callbacks(
  File "/home/airflow/.local/lib/python3.12/site-packages/airflow/models/taskinstance.py", line 3161, in _execute_task_with_callbacks
    result = self._execute_task(context, task_orig)
             ^^^^^^^^^^^^^^^^^^^^^^^^^^^^^^^^^^^^^^
  File "/home/airflow/.local/lib/python3.12/site-packages/airflow/models/taskinstance.py", line 3185, in _execute_task
    return _execute_task(self, context, task_orig)
           ^^^^^^^^^^^^^^^^^^^^^^^^^^^^^^^^^^^^^^^
  File "/home/airflow/.local/lib/python3.12/site-packages/airflow/models/taskinstance.py", line 768, in _execute_task
    result = _execute_callable(context=context, **execute_callable_kwargs)
             ^^^^^^^^^^^^^^^^^^^^^^^^^^^^^^^^^^^^^^^^^^^^^^^^^^^^^^^^^^^^^
  File "/home/airflow/.local/lib/python3.12/site-packages/airflow/models/taskinstance.py", line 734, in _execute_callable
    return ExecutionCallableRunner(
           ^^^^^^^^^^^^^^^^^^^^^^^^
  File "/home/airflow/.local/lib/python3.12/site-packages/airflow/utils/operator_helpers.py", line 252, in run
    return self.func(*args, **kwargs)
           ^^^^^^^^^^^^^^^^^^^^^^^^^^
  File "/home/airflow/.local/lib/python3.12/site-packages/airflow/models/baseoperator.py", line 424, in wrapper
    return func(self, *args, **kwargs)
           ^^^^^^^^^^^^^^^^^^^^^^^^^^^
  File "/home/airflow/.local/lib/python3.12/site-packages/airflow/decorators/base.py", line 266, in execute
    return_value = super().execute(context)
                   ^^^^^^^^^^^^^^^^^^^^^^^^
  File "/home/airflow/.local/lib/python3.12/site-packages/airflow/models/baseoperator.py", line 424, in wrapper
    return func(self, *args, **kwargs)
           ^^^^^^^^^^^^^^^^^^^^^^^^^^^
  File "/home/airflow/.local/lib/python3.12/site-packages/airflow/operators/python.py", line 238, in execute
    return_value = self.execute_callable()
                   ^^^^^^^^^^^^^^^^^^^^^^^
  File "/home/airflow/.local/lib/python3.12/site-packages/airflow/operators/python.py", line 256, in execute_callable
    return runner.run(*self.op_args, **self.op_kwargs)
           ^^^^^^^^^^^^^^^^^^^^^^^^^^^^^^^^^^^^^^^^^^^
  File "/home/airflow/.local/lib/python3.12/site-packages/airflow/utils/operator_helpers.py", line 252, in run
    return self.func(*args, **kwargs)
           ^^^^^^^^^^^^^^^^^^^^^^^^^^
  File "/opt/airflow/dags/etl.py", line 59, in extract_book_data
    metadata_dataset = load_dataset("McAuley-Lab/Amazon-Reviews-2023", "raw_meta_Kindle_Store", trust_remote_code=True,num_proc=16,split = 'full')
                       ^^^^^^^^^^^^^^^^^^^^^^^^^^^^^^^^^^^^^^^^^^^^^^^^^^^^^^^^^^^^^^^^^^^^^^^^^^^^^^^^^^^^^^^^^^^^^^^^^^^^^^^^^^^^^^^^^^^^^^^^^^^
  File "/home/airflow/.local/lib/python3.12/site-packages/datasets/load.py", line 2083, in load_dataset
    builder_instance.download_and_prepare(
  File "/home/airflow/.local/lib/python3.12/site-packages/datasets/builder.py", line 925, in download_and_prepare
    self._download_and_prepare(
  File "/home/airflow/.local/lib/python3.12/site-packages/datasets/builder.py", line 1649, in _download_and_prepare
    super()._download_and_prepare(
  File "/home/airflow/.local/lib/python3.12/site-packages/datasets/builder.py", line 979, in _download_and_prepare
    split_generators = self._split_generators(dl_manager, **split_generators_kwargs)
                       ^^^^^^^^^^^^^^^^^^^^^^^^^^^^^^^^^^^^^^^^^^^^^^^^^^^^^^^^^^^^^
  File "/home/airflow/.cache/huggingface/modules/datasets_modules/datasets/McAuley-Lab--Amazon-Reviews-2023/16b76e0823d73bb8cff1e9c5e3e37dbc46ae3daee380417ae141f5e67d3ea8e8/Amazon-Reviews-2023.py", line 509, in _split_generators
    dl_dir = dl_manager.download_and_extract(self.config.data_dir)
             ^^^^^^^^^^^^^^^^^^^^^^^^^^^^^^^^^^^^^^^^^^^^^^^^^^^^^
  File "/home/airflow/.local/lib/python3.12/site-packages/datasets/download/download_manager.py", line 326, in download_and_extract
    return self.extract(self.download(url_or_urls))
                        ^^^^^^^^^^^^^^^^^^^^^^^^^^
  File "/home/airflow/.local/lib/python3.12/site-packages/datasets/download/download_manager.py", line 159, in download
    downloaded_path_or_paths = map_nested(
                               ^^^^^^^^^^^
  File "/home/airflow/.local/lib/python3.12/site-packages/datasets/utils/py_utils.py", line 486, in map_nested
    mapped = function(data_struct)
             ^^^^^^^^^^^^^^^^^^^^^
  File "/home/airflow/.local/lib/python3.12/site-packages/datasets/download/download_manager.py", line 220, in _download_batched
    self._download_single(url_or_filename, download_config=download_config)
  File "/home/airflow/.local/lib/python3.12/site-packages/datasets/download/download_manager.py", line 229, in _download_single
    out = cached_path(url_or_filename, download_config=download_config)
          ^^^^^^^^^^^^^^^^^^^^^^^^^^^^^^^^^^^^^^^^^^^^^^^^^^^^^^^^^^^^^
  File "/home/airflow/.local/lib/python3.12/site-packages/datasets/utils/file_utils.py", line 189, in cached_path
    ).hf_hub_download(
      ^^^^^^^^^^^^^^^^
  File "/home/airflow/.local/lib/python3.12/site-packages/huggingface_hub/utils/_validators.py", line 114, in _inner_fn
    return fn(*args, **kwargs)
           ^^^^^^^^^^^^^^^^^^^
  File "/home/airflow/.local/lib/python3.12/site-packages/huggingface_hub/hf_api.py", line 5248, in hf_hub_download
    return hf_hub_download(
           ^^^^^^^^^^^^^^^^
  File "/home/airflow/.local/lib/python3.12/site-packages/huggingface_hub/utils/_validators.py", line 114, in _inner_fn
    return fn(*args, **kwargs)
           ^^^^^^^^^^^^^^^^^^^
  File "/home/airflow/.local/lib/python3.12/site-packages/huggingface_hub/file_download.py", line 862, in hf_hub_download
    return _hf_hub_download_to_cache_dir(
           ^^^^^^^^^^^^^^^^^^^^^^^^^^^^^^
  File "/home/airflow/.local/lib/python3.12/site-packages/huggingface_hub/file_download.py", line 1011, in _hf_hub_download_to_cache_dir
    _download_to_tmp_and_move(
  File "/home/airflow/.local/lib/python3.12/site-packages/huggingface_hub/file_download.py", line 1547, in _download_to_tmp_and_move
    http_get(
  File "/home/airflow/.local/lib/python3.12/site-packages/huggingface_hub/file_download.py", line 471, in http_get
    return http_get(
           ^^^^^^^^^
  File "/home/airflow/.local/lib/python3.12/site-packages/huggingface_hub/file_download.py", line 371, in http_get
    r = _request_wrapper(
        ^^^^^^^^^^^^^^^^^
  File "/home/airflow/.local/lib/python3.12/site-packages/huggingface_hub/file_download.py", line 303, in _request_wrapper
    response = get_session().request(method=method, url=url, **params)
               ^^^^^^^^^^^^^^^^^^^^^^^^^^^^^^^^^^^^^^^^^^^^^^^^^^^^^^^
  File "/home/airflow/.local/lib/python3.12/site-packages/requests/sessions.py", line 589, in request
    resp = self.send(prep, **send_kwargs)
           ^^^^^^^^^^^^^^^^^^^^^^^^^^^^^^
  File "/home/airflow/.local/lib/python3.12/site-packages/requests/sessions.py", line 703, in send
    r = adapter.send(request, **kwargs)
        ^^^^^^^^^^^^^^^^^^^^^^^^^^^^^^^
  File "/home/airflow/.local/lib/python3.12/site-packages/huggingface_hub/utils/_http.py", line 96, in send
    return super().send(request, *args, **kwargs)
           ^^^^^^^^^^^^^^^^^^^^^^^^^^^^^^^^^^^^^^
  File "/home/airflow/.local/lib/python3.12/site-packages/requests/adapters.py", line 700, in send
    raise ConnectionError(e, request=request)
requests.exceptions.ConnectionError: (MaxRetryError('HTTPSConnectionPool(host=\'cdn-lfs-us-1.hf.co\', port=443): Max retries exceeded with url: /repos/e9/40/e940a8d106b2e3986d1f8b7626c5a3f4fced3c1f43b992d12b1d465b58efc824/acdaba5f1fb83805a2bf032ba3c7ddb83c695b03d6c41b785a81070d3b66a145?response-content-disposition=inline%3B+filename*%3DUTF-8%27%27meta_Kindle_Store.jsonl%3B+filename%3D%22meta_Kindle_Store.jsonl%22%3B&Expires=1742297250&Policy=eyJTdGF0ZW1lbnQiOlt7IkNvbmRpdGlvbiI6eyJEYXRlTGVzc1RoYW4iOnsiQVdTOkVwb2NoVGltZSI6MTc0MjI5NzI1MH19LCJSZXNvdXJjZSI6Imh0dHBzOi8vY2RuLWxmcy11cy0xLmhmLmNvL3JlcG9zL2U5LzQwL2U5NDBhOGQxMDZiMmUzOTg2ZDFmOGI3NjI2YzVhM2Y0ZmNlZDNjMWY0M2I5OTJkMTJiMWQ0NjViNThlZmM4MjQvYWNkYWJhNWYxZmI4MzgwNWEyYmYwMzJiYTNjN2RkYjgzYzY5NWIwM2Q2YzQxYjc4NWE4MTA3MGQzYjY2YTE0NT9yZXNwb25zZS1jb250ZW50LWRpc3Bvc2l0aW9uPSoifV19&Signature=cUrd65YLxbZOtfWJypM~v6X85lNUMyamP-BS60Ue00dl0KoOMkWxAwzLt66nhcW1is0THVEUuk2jRBIFH~Oj2xAaThWl00Sbeidqp1hjNDJOiCerKynU0lTzk4XBJj0xA1RvVlB2KNLCa13wkaSI-ovGj1xt~ZB-GvjaxqrX2nJ6TSjaEOnLy9xMnfJ7KGD9ca62ym4r2ayifwgLKVTAF5sVO8BZ5mZ99Qm2uy3na99x9V2iavrBWI-vrjzKOd9ZJmvqNxChJdLLA3YHYmNgQ7~QffHGnbonD5isnRcadKU4vOVAH72XLT0ak5kYCbonIBnYw5qSgoO6ahzJzxBMWw__&Key-Pair-Id=K24J24Z295AEI9 (Caused by NameResolutionError("<urllib3.connection.HTTPSConnection object at 0xffff3f3432c0>: Failed to resolve \'cdn-lfs-us-1.hf.co\' ([Errno -2] Name or service not known)"))'), '(Request ID: 3f32ae61-0f86-436e-8993-db4af34bd365)')
[2025-03-18T10:40:54.925+0000] {local_task_job_runner.py:266} INFO - Task exited with return code 1
[2025-03-18T10:40:54.936+0000] {taskinstance.py:3901} INFO - 0 downstream tasks scheduled from follow-on schedule check
[2025-03-18T10:40:54.938+0000] {local_task_job_runner.py:245} INFO - ::endgroup::
