[2025-03-14T17:32:53.995+0000] {local_task_job_runner.py:123} INFO - ::group::Pre task execution logs
[2025-03-14T17:32:54.003+0000] {taskinstance.py:2614} INFO - Dependencies all met for dep_context=non-requeueable deps ti=<TaskInstance: kindle_store_etl_taskflow.transform_data manual__2025-03-14T17:08:40.918741+00:00 [queued]>
[2025-03-14T17:32:54.005+0000] {taskinstance.py:2614} INFO - Dependencies all met for dep_context=requeueable deps ti=<TaskInstance: kindle_store_etl_taskflow.transform_data manual__2025-03-14T17:08:40.918741+00:00 [queued]>
[2025-03-14T17:32:54.006+0000] {taskinstance.py:2867} INFO - Starting attempt 1 of 1
[2025-03-14T17:32:54.010+0000] {taskinstance.py:2890} INFO - Executing <Task(_PythonDecoratedOperator): transform_data> on 2025-03-14 17:08:40.918741+00:00
[2025-03-14T17:32:54.014+0000] {warnings.py:112} WARNING - /home/***/.local/lib/python3.12/site-packages/***/task/task_runner/standard_task_runner.py:70: DeprecationWarning: This process (pid=688) is multi-threaded, use of fork() may lead to deadlocks in the child.
  pid = os.fork()

[2025-03-14T17:32:54.014+0000] {standard_task_runner.py:72} INFO - Started process 689 to run task
[2025-03-14T17:32:54.015+0000] {standard_task_runner.py:104} INFO - Running: ['***', 'tasks', 'run', 'kindle_store_etl_taskflow', 'transform_data', 'manual__2025-03-14T17:08:40.918741+00:00', '--job-id', '9', '--raw', '--subdir', 'DAGS_FOLDER/etl.py', '--cfg-path', '/tmp/tmpjioqts1p']
[2025-03-14T17:32:54.015+0000] {standard_task_runner.py:105} INFO - Job 9: Subtask transform_data
[2025-03-14T17:32:54.042+0000] {task_command.py:467} INFO - Running <TaskInstance: kindle_store_etl_taskflow.transform_data manual__2025-03-14T17:08:40.918741+00:00 [running]> on host 76178626723b
[2025-03-14T17:32:54.070+0000] {taskinstance.py:3134} INFO - Exporting env vars: AIRFLOW_CTX_DAG_OWNER='***' AIRFLOW_CTX_DAG_ID='kindle_store_etl_taskflow' AIRFLOW_CTX_TASK_ID='transform_data' AIRFLOW_CTX_EXECUTION_DATE='2025-03-14T17:08:40.918741+00:00' AIRFLOW_CTX_TRY_NUMBER='1' AIRFLOW_CTX_DAG_RUN_ID='manual__2025-03-14T17:08:40.918741+00:00'
[2025-03-14T17:32:54.071+0000] {logging_mixin.py:190} INFO - Task instance is in running state
[2025-03-14T17:32:54.071+0000] {logging_mixin.py:190} INFO -  Previous state of the Task instance: queued
[2025-03-14T17:32:54.071+0000] {logging_mixin.py:190} INFO - Current task name:transform_data state:running start_date:2025-03-14 17:32:54.003273+00:00
[2025-03-14T17:32:54.071+0000] {logging_mixin.py:190} INFO - Dag name:kindle_store_etl_taskflow and current dag run status:running
[2025-03-14T17:32:54.071+0000] {taskinstance.py:732} INFO - ::endgroup::
[2025-03-14T17:32:54.078+0000] {taskinstance.py:3313} ERROR - Task failed with exception
Traceback (most recent call last):
  File "/home/airflow/.local/lib/python3.12/site-packages/airflow/models/taskinstance.py", line 768, in _execute_task
    result = _execute_callable(context=context, **execute_callable_kwargs)
             ^^^^^^^^^^^^^^^^^^^^^^^^^^^^^^^^^^^^^^^^^^^^^^^^^^^^^^^^^^^^^
  File "/home/airflow/.local/lib/python3.12/site-packages/airflow/models/taskinstance.py", line 734, in _execute_callable
    return ExecutionCallableRunner(
           ^^^^^^^^^^^^^^^^^^^^^^^^
  File "/home/airflow/.local/lib/python3.12/site-packages/airflow/utils/operator_helpers.py", line 252, in run
    return self.func(*args, **kwargs)
           ^^^^^^^^^^^^^^^^^^^^^^^^^^
  File "/home/airflow/.local/lib/python3.12/site-packages/airflow/models/baseoperator.py", line 424, in wrapper
    return func(self, *args, **kwargs)
           ^^^^^^^^^^^^^^^^^^^^^^^^^^^
  File "/home/airflow/.local/lib/python3.12/site-packages/airflow/decorators/base.py", line 266, in execute
    return_value = super().execute(context)
                   ^^^^^^^^^^^^^^^^^^^^^^^^
  File "/home/airflow/.local/lib/python3.12/site-packages/airflow/models/baseoperator.py", line 424, in wrapper
    return func(self, *args, **kwargs)
           ^^^^^^^^^^^^^^^^^^^^^^^^^^^
  File "/home/airflow/.local/lib/python3.12/site-packages/airflow/operators/python.py", line 238, in execute
    return_value = self.execute_callable()
                   ^^^^^^^^^^^^^^^^^^^^^^^
  File "/home/airflow/.local/lib/python3.12/site-packages/airflow/operators/python.py", line 256, in execute_callable
    return runner.run(*self.op_args, **self.op_kwargs)
           ^^^^^^^^^^^^^^^^^^^^^^^^^^^^^^^^^^^^^^^^^^^
  File "/home/airflow/.local/lib/python3.12/site-packages/airflow/utils/operator_helpers.py", line 252, in run
    return self.func(*args, **kwargs)
           ^^^^^^^^^^^^^^^^^^^^^^^^^^
  File "/opt/airflow/dags/etl.py", line 45, in transform_data
    reviews_df = pd.read_parquet(file_paths["reviews_path"])
                 ^^^^^^^^^^^^^^^^^^^^^^^^^^^^^^^^^^^^^^^^^^^
  File "/home/airflow/.local/lib/python3.12/site-packages/pandas/io/parquet.py", line 670, in read_parquet
    return impl.read(
           ^^^^^^^^^^
  File "/home/airflow/.local/lib/python3.12/site-packages/pandas/io/parquet.py", line 272, in read
    pa_table = self.api.parquet.read_table(
               ^^^^^^^^^^^^^^^^^^^^^^^^^^^^
  File "/home/airflow/.local/lib/python3.12/site-packages/pyarrow/parquet/core.py", line 1793, in read_table
    dataset = ParquetDataset(
              ^^^^^^^^^^^^^^^
  File "/home/airflow/.local/lib/python3.12/site-packages/pyarrow/parquet/core.py", line 1371, in __init__
    self._dataset = ds.dataset(path_or_paths, filesystem=filesystem,
                    ^^^^^^^^^^^^^^^^^^^^^^^^^^^^^^^^^^^^^^^^^^^^^^^^
  File "/home/airflow/.local/lib/python3.12/site-packages/pyarrow/dataset.py", line 794, in dataset
    return _filesystem_dataset(source, **kwargs)
           ^^^^^^^^^^^^^^^^^^^^^^^^^^^^^^^^^^^^^
  File "/home/airflow/.local/lib/python3.12/site-packages/pyarrow/dataset.py", line 486, in _filesystem_dataset
    return factory.finish(schema)
           ^^^^^^^^^^^^^^^^^^^^^^
  File "pyarrow/_dataset.pyx", line 3138, in pyarrow._dataset.DatasetFactory.finish
  File "pyarrow/error.pxi", line 155, in pyarrow.lib.pyarrow_internal_check_status
  File "pyarrow/error.pxi", line 92, in pyarrow.lib.check_status
pyarrow.lib.ArrowInvalid: Error creating dataset. Could not read schema from '/opt/***/dataset/kindle_reviews.parquet/dataset_dict.json'. Is this a 'parquet' file?: Could not open Parquet input source '/opt/***/dataset/kindle_reviews.parquet/dataset_dict.json': Parquet magic bytes not found in footer. Either the file is corrupted or this is not a parquet file.
[2025-03-14T17:32:54.085+0000] {logging_mixin.py:190} INFO - Task instance in failure state
[2025-03-14T17:32:54.086+0000] {logging_mixin.py:190} INFO - Task start:2025-03-14 17:32:54.003273+00:00 end:2025-03-14 17:32:54.085751+00:00 duration:0.082478
[2025-03-14T17:32:54.086+0000] {logging_mixin.py:190} INFO - Task:<Task(_PythonDecoratedOperator): transform_data> dag:<DAG: kindle_store_etl_taskflow> dagrun:<DagRun kindle_store_etl_taskflow @ 2025-03-14 17:08:40.918741+00:00: manual__2025-03-14T17:08:40.918741+00:00, state:running, queued_at: 2025-03-14 17:08:40.922139+00:00. externally triggered: True>
[2025-03-14T17:32:54.086+0000] {logging_mixin.py:190} INFO - Failure caused by Error creating dataset. Could not read schema from '/opt/***/dataset/kindle_reviews.parquet/dataset_dict.json'. Is this a 'parquet' file?: Could not open Parquet input source '/opt/***/dataset/kindle_reviews.parquet/dataset_dict.json': Parquet magic bytes not found in footer. Either the file is corrupted or this is not a parquet file.
[2025-03-14T17:32:54.086+0000] {taskinstance.py:1226} INFO - Marking task as FAILED. dag_id=kindle_store_etl_taskflow, task_id=transform_data, run_id=manual__2025-03-14T17:08:40.918741+00:00, execution_date=20250314T170840, start_date=20250314T173254, end_date=20250314T173254
[2025-03-14T17:32:54.095+0000] {taskinstance.py:341} INFO - ::group::Post task execution logs
[2025-03-14T17:32:54.095+0000] {standard_task_runner.py:124} ERROR - Failed to execute job 9 for task transform_data (Error creating dataset. Could not read schema from '/opt/***/dataset/kindle_reviews.parquet/dataset_dict.json'. Is this a 'parquet' file?: Could not open Parquet input source '/opt/***/dataset/kindle_reviews.parquet/dataset_dict.json': Parquet magic bytes not found in footer. Either the file is corrupted or this is not a parquet file.; 689)
Traceback (most recent call last):
  File "/home/airflow/.local/lib/python3.12/site-packages/airflow/task/task_runner/standard_task_runner.py", line 117, in _start_by_fork
    ret = args.func(args, dag=self.dag)
          ^^^^^^^^^^^^^^^^^^^^^^^^^^^^^
  File "/home/airflow/.local/lib/python3.12/site-packages/airflow/cli/cli_config.py", line 49, in command
    return func(*args, **kwargs)
           ^^^^^^^^^^^^^^^^^^^^^
  File "/home/airflow/.local/lib/python3.12/site-packages/airflow/utils/cli.py", line 116, in wrapper
    return f(*args, **kwargs)
           ^^^^^^^^^^^^^^^^^^
  File "/home/airflow/.local/lib/python3.12/site-packages/airflow/cli/commands/task_command.py", line 483, in task_run
    task_return_code = _run_task_by_selected_method(args, _dag, ti)
                       ^^^^^^^^^^^^^^^^^^^^^^^^^^^^^^^^^^^^^^^^^^^^
  File "/home/airflow/.local/lib/python3.12/site-packages/airflow/cli/commands/task_command.py", line 256, in _run_task_by_selected_method
    return _run_raw_task(args, ti)
           ^^^^^^^^^^^^^^^^^^^^^^^
  File "/home/airflow/.local/lib/python3.12/site-packages/airflow/cli/commands/task_command.py", line 341, in _run_raw_task
    return ti._run_raw_task(
           ^^^^^^^^^^^^^^^^^
  File "/home/airflow/.local/lib/python3.12/site-packages/airflow/utils/session.py", line 97, in wrapper
    return func(*args, session=session, **kwargs)
           ^^^^^^^^^^^^^^^^^^^^^^^^^^^^^^^^^^^^^^
  File "/home/airflow/.local/lib/python3.12/site-packages/airflow/models/taskinstance.py", line 3006, in _run_raw_task
    return _run_raw_task(
           ^^^^^^^^^^^^^^
  File "/home/airflow/.local/lib/python3.12/site-packages/airflow/models/taskinstance.py", line 274, in _run_raw_task
    TaskInstance._execute_task_with_callbacks(
  File "/home/airflow/.local/lib/python3.12/site-packages/airflow/models/taskinstance.py", line 3161, in _execute_task_with_callbacks
    result = self._execute_task(context, task_orig)
             ^^^^^^^^^^^^^^^^^^^^^^^^^^^^^^^^^^^^^^
  File "/home/airflow/.local/lib/python3.12/site-packages/airflow/models/taskinstance.py", line 3185, in _execute_task
    return _execute_task(self, context, task_orig)
           ^^^^^^^^^^^^^^^^^^^^^^^^^^^^^^^^^^^^^^^
  File "/home/airflow/.local/lib/python3.12/site-packages/airflow/models/taskinstance.py", line 768, in _execute_task
    result = _execute_callable(context=context, **execute_callable_kwargs)
             ^^^^^^^^^^^^^^^^^^^^^^^^^^^^^^^^^^^^^^^^^^^^^^^^^^^^^^^^^^^^^
  File "/home/airflow/.local/lib/python3.12/site-packages/airflow/models/taskinstance.py", line 734, in _execute_callable
    return ExecutionCallableRunner(
           ^^^^^^^^^^^^^^^^^^^^^^^^
  File "/home/airflow/.local/lib/python3.12/site-packages/airflow/utils/operator_helpers.py", line 252, in run
    return self.func(*args, **kwargs)
           ^^^^^^^^^^^^^^^^^^^^^^^^^^
  File "/home/airflow/.local/lib/python3.12/site-packages/airflow/models/baseoperator.py", line 424, in wrapper
    return func(self, *args, **kwargs)
           ^^^^^^^^^^^^^^^^^^^^^^^^^^^
  File "/home/airflow/.local/lib/python3.12/site-packages/airflow/decorators/base.py", line 266, in execute
    return_value = super().execute(context)
                   ^^^^^^^^^^^^^^^^^^^^^^^^
  File "/home/airflow/.local/lib/python3.12/site-packages/airflow/models/baseoperator.py", line 424, in wrapper
    return func(self, *args, **kwargs)
           ^^^^^^^^^^^^^^^^^^^^^^^^^^^
  File "/home/airflow/.local/lib/python3.12/site-packages/airflow/operators/python.py", line 238, in execute
    return_value = self.execute_callable()
                   ^^^^^^^^^^^^^^^^^^^^^^^
  File "/home/airflow/.local/lib/python3.12/site-packages/airflow/operators/python.py", line 256, in execute_callable
    return runner.run(*self.op_args, **self.op_kwargs)
           ^^^^^^^^^^^^^^^^^^^^^^^^^^^^^^^^^^^^^^^^^^^
  File "/home/airflow/.local/lib/python3.12/site-packages/airflow/utils/operator_helpers.py", line 252, in run
    return self.func(*args, **kwargs)
           ^^^^^^^^^^^^^^^^^^^^^^^^^^
  File "/opt/airflow/dags/etl.py", line 45, in transform_data
    reviews_df = pd.read_parquet(file_paths["reviews_path"])
                 ^^^^^^^^^^^^^^^^^^^^^^^^^^^^^^^^^^^^^^^^^^^
  File "/home/airflow/.local/lib/python3.12/site-packages/pandas/io/parquet.py", line 670, in read_parquet
    return impl.read(
           ^^^^^^^^^^
  File "/home/airflow/.local/lib/python3.12/site-packages/pandas/io/parquet.py", line 272, in read
    pa_table = self.api.parquet.read_table(
               ^^^^^^^^^^^^^^^^^^^^^^^^^^^^
  File "/home/airflow/.local/lib/python3.12/site-packages/pyarrow/parquet/core.py", line 1793, in read_table
    dataset = ParquetDataset(
              ^^^^^^^^^^^^^^^
  File "/home/airflow/.local/lib/python3.12/site-packages/pyarrow/parquet/core.py", line 1371, in __init__
    self._dataset = ds.dataset(path_or_paths, filesystem=filesystem,
                    ^^^^^^^^^^^^^^^^^^^^^^^^^^^^^^^^^^^^^^^^^^^^^^^^
  File "/home/airflow/.local/lib/python3.12/site-packages/pyarrow/dataset.py", line 794, in dataset
    return _filesystem_dataset(source, **kwargs)
           ^^^^^^^^^^^^^^^^^^^^^^^^^^^^^^^^^^^^^
  File "/home/airflow/.local/lib/python3.12/site-packages/pyarrow/dataset.py", line 486, in _filesystem_dataset
    return factory.finish(schema)
           ^^^^^^^^^^^^^^^^^^^^^^
  File "pyarrow/_dataset.pyx", line 3138, in pyarrow._dataset.DatasetFactory.finish
  File "pyarrow/error.pxi", line 155, in pyarrow.lib.pyarrow_internal_check_status
  File "pyarrow/error.pxi", line 92, in pyarrow.lib.check_status
pyarrow.lib.ArrowInvalid: Error creating dataset. Could not read schema from '/opt/***/dataset/kindle_reviews.parquet/dataset_dict.json'. Is this a 'parquet' file?: Could not open Parquet input source '/opt/***/dataset/kindle_reviews.parquet/dataset_dict.json': Parquet magic bytes not found in footer. Either the file is corrupted or this is not a parquet file.
[2025-03-14T17:32:54.115+0000] {local_task_job_runner.py:266} INFO - Task exited with return code 1
[2025-03-14T17:32:54.124+0000] {taskinstance.py:3901} INFO - 0 downstream tasks scheduled from follow-on schedule check
[2025-03-14T17:32:54.125+0000] {local_task_job_runner.py:245} INFO - ::endgroup::
