[2025-03-14T10:48:24.488+0000] {local_task_job_runner.py:123} INFO - ::group::Pre task execution logs
[2025-03-14T10:48:24.495+0000] {taskinstance.py:2614} INFO - Dependencies all met for dep_context=non-requeueable deps ti=<TaskInstance: ecommerce_etl_taskflow.create_table manual__2025-03-14T10:48:23.648516+00:00 [queued]>
[2025-03-14T10:48:24.498+0000] {taskinstance.py:2614} INFO - Dependencies all met for dep_context=requeueable deps ti=<TaskInstance: ecommerce_etl_taskflow.create_table manual__2025-03-14T10:48:23.648516+00:00 [queued]>
[2025-03-14T10:48:24.498+0000] {taskinstance.py:2867} INFO - Starting attempt 1 of 4
[2025-03-14T10:48:24.503+0000] {taskinstance.py:2890} INFO - Executing <Task(_PythonDecoratedOperator): create_table> on 2025-03-14 10:48:23.648516+00:00
[2025-03-14T10:48:24.507+0000] {warnings.py:112} WARNING - /home/***/.local/lib/python3.12/site-packages/***/task/task_runner/standard_task_runner.py:70: DeprecationWarning: This process (pid=614) is multi-threaded, use of fork() may lead to deadlocks in the child.
  pid = os.fork()

[2025-03-14T10:48:24.507+0000] {standard_task_runner.py:72} INFO - Started process 616 to run task
[2025-03-14T10:48:24.508+0000] {standard_task_runner.py:104} INFO - Running: ['***', 'tasks', 'run', 'ecommerce_etl_taskflow', 'create_table', 'manual__2025-03-14T10:48:23.648516+00:00', '--job-id', '13', '--raw', '--subdir', 'DAGS_FOLDER/IS3107 Data Engineering DAG Demo Taskflow.py', '--cfg-path', '/tmp/tmpfpotjuui']
[2025-03-14T10:48:24.509+0000] {standard_task_runner.py:105} INFO - Job 13: Subtask create_table
[2025-03-14T10:48:24.533+0000] {task_command.py:467} INFO - Running <TaskInstance: ecommerce_etl_taskflow.create_table manual__2025-03-14T10:48:23.648516+00:00 [running]> on host a8f81b9151e8
[2025-03-14T10:48:24.686+0000] {taskinstance.py:3134} INFO - Exporting env vars: AIRFLOW_CTX_DAG_EMAIL='***@example.com' AIRFLOW_CTX_DAG_OWNER='***' AIRFLOW_CTX_DAG_ID='ecommerce_etl_taskflow' AIRFLOW_CTX_TASK_ID='create_table' AIRFLOW_CTX_EXECUTION_DATE='2025-03-14T10:48:23.648516+00:00' AIRFLOW_CTX_TRY_NUMBER='1' AIRFLOW_CTX_DAG_RUN_ID='manual__2025-03-14T10:48:23.648516+00:00'
[2025-03-14T10:48:24.686+0000] {logging_mixin.py:190} INFO - Task instance is in running state
[2025-03-14T10:48:24.686+0000] {logging_mixin.py:190} INFO -  Previous state of the Task instance: queued
[2025-03-14T10:48:24.686+0000] {logging_mixin.py:190} INFO - Current task name:create_table state:running start_date:2025-03-14 10:48:24.495779+00:00
[2025-03-14T10:48:24.687+0000] {logging_mixin.py:190} INFO - Dag name:ecommerce_etl_taskflow and current dag run status:running
[2025-03-14T10:48:24.687+0000] {taskinstance.py:732} INFO - ::endgroup::
[2025-03-14T10:48:24.690+0000] {base.py:84} INFO - Retrieving connection 'postgres_t5'
[2025-03-14T10:48:24.692+0000] {taskinstance.py:3313} ERROR - Task failed with exception
Traceback (most recent call last):
  File "/home/airflow/.local/lib/python3.12/site-packages/airflow/models/taskinstance.py", line 768, in _execute_task
    result = _execute_callable(context=context, **execute_callable_kwargs)
             ^^^^^^^^^^^^^^^^^^^^^^^^^^^^^^^^^^^^^^^^^^^^^^^^^^^^^^^^^^^^^
  File "/home/airflow/.local/lib/python3.12/site-packages/airflow/models/taskinstance.py", line 734, in _execute_callable
    return ExecutionCallableRunner(
           ^^^^^^^^^^^^^^^^^^^^^^^^
  File "/home/airflow/.local/lib/python3.12/site-packages/airflow/utils/operator_helpers.py", line 252, in run
    return self.func(*args, **kwargs)
           ^^^^^^^^^^^^^^^^^^^^^^^^^^
  File "/home/airflow/.local/lib/python3.12/site-packages/airflow/models/baseoperator.py", line 424, in wrapper
    return func(self, *args, **kwargs)
           ^^^^^^^^^^^^^^^^^^^^^^^^^^^
  File "/home/airflow/.local/lib/python3.12/site-packages/airflow/decorators/base.py", line 266, in execute
    return_value = super().execute(context)
                   ^^^^^^^^^^^^^^^^^^^^^^^^
  File "/home/airflow/.local/lib/python3.12/site-packages/airflow/models/baseoperator.py", line 424, in wrapper
    return func(self, *args, **kwargs)
           ^^^^^^^^^^^^^^^^^^^^^^^^^^^
  File "/home/airflow/.local/lib/python3.12/site-packages/airflow/operators/python.py", line 238, in execute
    return_value = self.execute_callable()
                   ^^^^^^^^^^^^^^^^^^^^^^^
  File "/home/airflow/.local/lib/python3.12/site-packages/airflow/operators/python.py", line 256, in execute_callable
    return runner.run(*self.op_args, **self.op_kwargs)
           ^^^^^^^^^^^^^^^^^^^^^^^^^^^^^^^^^^^^^^^^^^^
  File "/home/airflow/.local/lib/python3.12/site-packages/airflow/utils/operator_helpers.py", line 252, in run
    return self.func(*args, **kwargs)
           ^^^^^^^^^^^^^^^^^^^^^^^^^^
  File "/opt/airflow/dags/IS3107 Data Engineering DAG Demo Taskflow.py", line 37, in create_table
    hook.run(create_table_sql, autocommit=True)
  File "/home/airflow/.local/lib/python3.12/site-packages/airflow/providers/common/sql/hooks/sql.py", line 463, in run
    with self._create_autocommit_connection(autocommit) as conn:
         ^^^^^^^^^^^^^^^^^^^^^^^^^^^^^^^^^^^^^^^^^^^^^^
  File "/usr/local/lib/python3.12/contextlib.py", line 137, in __enter__
    return next(self.gen)
           ^^^^^^^^^^^^^^
  File "/home/airflow/.local/lib/python3.12/site-packages/airflow/providers/common/sql/hooks/sql.py", line 576, in _create_autocommit_connection
    with closing(self.get_conn()) as conn:
                 ^^^^^^^^^^^^^^^
  File "/home/airflow/.local/lib/python3.12/site-packages/airflow/providers/postgres/hooks/postgres.py", line 165, in get_conn
    self.conn = psycopg2.connect(**conn_args)
                ^^^^^^^^^^^^^^^^^^^^^^^^^^^^^
  File "/home/airflow/.local/lib/python3.12/site-packages/psycopg2/__init__.py", line 122, in connect
    conn = _connect(dsn, connection_factory=connection_factory, **kwasync)
           ^^^^^^^^^^^^^^^^^^^^^^^^^^^^^^^^^^^^^^^^^^^^^^^^^^^^^^^^^^^^^^^
psycopg2.OperationalError: connection to server at "postgres" (172.18.0.2), port 5432 failed: fe_sendauth: no password supplied

[2025-03-14T10:48:24.698+0000] {logging_mixin.py:190} INFO - Task instance in failure state
[2025-03-14T10:48:24.698+0000] {logging_mixin.py:190} INFO - Task start:2025-03-14 10:48:24.495779+00:00 end:2025-03-14 10:48:24.697994+00:00 duration:0.202215
[2025-03-14T10:48:24.698+0000] {logging_mixin.py:190} INFO - Task:<Task(_PythonDecoratedOperator): create_table> dag:<DAG: ecommerce_etl_taskflow> dagrun:<DagRun ecommerce_etl_taskflow @ 2025-03-14 10:48:23.648516+00:00: manual__2025-03-14T10:48:23.648516+00:00, state:running, queued_at: 2025-03-14 10:48:23.658729+00:00. externally triggered: True>
[2025-03-14T10:48:24.698+0000] {logging_mixin.py:190} INFO - Failure caused by connection to server at "postgres" (172.18.0.2), port 5432 failed: fe_sendauth: no password supplied
[2025-03-14T10:48:24.698+0000] {taskinstance.py:1226} INFO - Marking task as UP_FOR_RETRY. dag_id=ecommerce_etl_taskflow, task_id=create_table, run_id=manual__2025-03-14T10:48:23.648516+00:00, execution_date=20250314T104823, start_date=20250314T104824, end_date=20250314T104824
[2025-03-14T10:48:24.710+0000] {taskinstance.py:341} INFO - ::group::Post task execution logs
[2025-03-14T10:48:24.710+0000] {standard_task_runner.py:124} ERROR - Failed to execute job 13 for task create_table (connection to server at "postgres" (172.18.0.2), port 5432 failed: fe_sendauth: no password supplied
; 616)
Traceback (most recent call last):
  File "/home/airflow/.local/lib/python3.12/site-packages/airflow/task/task_runner/standard_task_runner.py", line 117, in _start_by_fork
    ret = args.func(args, dag=self.dag)
          ^^^^^^^^^^^^^^^^^^^^^^^^^^^^^
  File "/home/airflow/.local/lib/python3.12/site-packages/airflow/cli/cli_config.py", line 49, in command
    return func(*args, **kwargs)
           ^^^^^^^^^^^^^^^^^^^^^
  File "/home/airflow/.local/lib/python3.12/site-packages/airflow/utils/cli.py", line 116, in wrapper
    return f(*args, **kwargs)
           ^^^^^^^^^^^^^^^^^^
  File "/home/airflow/.local/lib/python3.12/site-packages/airflow/cli/commands/task_command.py", line 483, in task_run
    task_return_code = _run_task_by_selected_method(args, _dag, ti)
                       ^^^^^^^^^^^^^^^^^^^^^^^^^^^^^^^^^^^^^^^^^^^^
  File "/home/airflow/.local/lib/python3.12/site-packages/airflow/cli/commands/task_command.py", line 256, in _run_task_by_selected_method
    return _run_raw_task(args, ti)
           ^^^^^^^^^^^^^^^^^^^^^^^
  File "/home/airflow/.local/lib/python3.12/site-packages/airflow/cli/commands/task_command.py", line 341, in _run_raw_task
    return ti._run_raw_task(
           ^^^^^^^^^^^^^^^^^
  File "/home/airflow/.local/lib/python3.12/site-packages/airflow/utils/session.py", line 97, in wrapper
    return func(*args, session=session, **kwargs)
           ^^^^^^^^^^^^^^^^^^^^^^^^^^^^^^^^^^^^^^
  File "/home/airflow/.local/lib/python3.12/site-packages/airflow/models/taskinstance.py", line 3006, in _run_raw_task
    return _run_raw_task(
           ^^^^^^^^^^^^^^
  File "/home/airflow/.local/lib/python3.12/site-packages/airflow/models/taskinstance.py", line 274, in _run_raw_task
    TaskInstance._execute_task_with_callbacks(
  File "/home/airflow/.local/lib/python3.12/site-packages/airflow/models/taskinstance.py", line 3161, in _execute_task_with_callbacks
    result = self._execute_task(context, task_orig)
             ^^^^^^^^^^^^^^^^^^^^^^^^^^^^^^^^^^^^^^
  File "/home/airflow/.local/lib/python3.12/site-packages/airflow/models/taskinstance.py", line 3185, in _execute_task
    return _execute_task(self, context, task_orig)
           ^^^^^^^^^^^^^^^^^^^^^^^^^^^^^^^^^^^^^^^
  File "/home/airflow/.local/lib/python3.12/site-packages/airflow/models/taskinstance.py", line 768, in _execute_task
    result = _execute_callable(context=context, **execute_callable_kwargs)
             ^^^^^^^^^^^^^^^^^^^^^^^^^^^^^^^^^^^^^^^^^^^^^^^^^^^^^^^^^^^^^
  File "/home/airflow/.local/lib/python3.12/site-packages/airflow/models/taskinstance.py", line 734, in _execute_callable
    return ExecutionCallableRunner(
           ^^^^^^^^^^^^^^^^^^^^^^^^
  File "/home/airflow/.local/lib/python3.12/site-packages/airflow/utils/operator_helpers.py", line 252, in run
    return self.func(*args, **kwargs)
           ^^^^^^^^^^^^^^^^^^^^^^^^^^
  File "/home/airflow/.local/lib/python3.12/site-packages/airflow/models/baseoperator.py", line 424, in wrapper
    return func(self, *args, **kwargs)
           ^^^^^^^^^^^^^^^^^^^^^^^^^^^
  File "/home/airflow/.local/lib/python3.12/site-packages/airflow/decorators/base.py", line 266, in execute
    return_value = super().execute(context)
                   ^^^^^^^^^^^^^^^^^^^^^^^^
  File "/home/airflow/.local/lib/python3.12/site-packages/airflow/models/baseoperator.py", line 424, in wrapper
    return func(self, *args, **kwargs)
           ^^^^^^^^^^^^^^^^^^^^^^^^^^^
  File "/home/airflow/.local/lib/python3.12/site-packages/airflow/operators/python.py", line 238, in execute
    return_value = self.execute_callable()
                   ^^^^^^^^^^^^^^^^^^^^^^^
  File "/home/airflow/.local/lib/python3.12/site-packages/airflow/operators/python.py", line 256, in execute_callable
    return runner.run(*self.op_args, **self.op_kwargs)
           ^^^^^^^^^^^^^^^^^^^^^^^^^^^^^^^^^^^^^^^^^^^
  File "/home/airflow/.local/lib/python3.12/site-packages/airflow/utils/operator_helpers.py", line 252, in run
    return self.func(*args, **kwargs)
           ^^^^^^^^^^^^^^^^^^^^^^^^^^
  File "/opt/airflow/dags/IS3107 Data Engineering DAG Demo Taskflow.py", line 37, in create_table
    hook.run(create_table_sql, autocommit=True)
  File "/home/airflow/.local/lib/python3.12/site-packages/airflow/providers/common/sql/hooks/sql.py", line 463, in run
    with self._create_autocommit_connection(autocommit) as conn:
         ^^^^^^^^^^^^^^^^^^^^^^^^^^^^^^^^^^^^^^^^^^^^^^
  File "/usr/local/lib/python3.12/contextlib.py", line 137, in __enter__
    return next(self.gen)
           ^^^^^^^^^^^^^^
  File "/home/airflow/.local/lib/python3.12/site-packages/airflow/providers/common/sql/hooks/sql.py", line 576, in _create_autocommit_connection
    with closing(self.get_conn()) as conn:
                 ^^^^^^^^^^^^^^^
  File "/home/airflow/.local/lib/python3.12/site-packages/airflow/providers/postgres/hooks/postgres.py", line 165, in get_conn
    self.conn = psycopg2.connect(**conn_args)
                ^^^^^^^^^^^^^^^^^^^^^^^^^^^^^
  File "/home/airflow/.local/lib/python3.12/site-packages/psycopg2/__init__.py", line 122, in connect
    conn = _connect(dsn, connection_factory=connection_factory, **kwasync)
           ^^^^^^^^^^^^^^^^^^^^^^^^^^^^^^^^^^^^^^^^^^^^^^^^^^^^^^^^^^^^^^^
psycopg2.OperationalError: connection to server at "postgres" (172.18.0.2), port 5432 failed: fe_sendauth: no password supplied

[2025-03-14T10:48:24.733+0000] {local_task_job_runner.py:266} INFO - Task exited with return code 1
[2025-03-14T10:48:24.744+0000] {taskinstance.py:3901} INFO - 0 downstream tasks scheduled from follow-on schedule check
[2025-03-14T10:48:24.745+0000] {local_task_job_runner.py:245} INFO - ::endgroup::
