[2025-04-20T00:11:23.591+0000] {local_task_job_runner.py:123} INFO - ::group::Pre task execution logs
[2025-04-20T00:11:23.598+0000] {taskinstance.py:2614} INFO - Dependencies all met for dep_context=non-requeueable deps ti=<TaskInstance: kindle_store_etl_taskflow.extract_review_data scheduled__2025-04-13T00:00:00+00:00 [queued]>
[2025-04-20T00:11:23.601+0000] {taskinstance.py:2614} INFO - Dependencies all met for dep_context=requeueable deps ti=<TaskInstance: kindle_store_etl_taskflow.extract_review_data scheduled__2025-04-13T00:00:00+00:00 [queued]>
[2025-04-20T00:11:23.602+0000] {taskinstance.py:2867} INFO - Starting attempt 1 of 1
[2025-04-20T00:11:23.607+0000] {taskinstance.py:2890} INFO - Executing <Task(_PythonDecoratedOperator): extract_review_data> on 2025-04-13 00:00:00+00:00
[2025-04-20T00:11:23.612+0000] {warnings.py:112} WARNING - /home/***/.local/lib/python3.12/site-packages/***/task/task_runner/standard_task_runner.py:70: DeprecationWarning: This process (pid=1079) is multi-threaded, use of fork() may lead to deadlocks in the child.
  pid = os.fork()

[2025-04-20T00:11:23.613+0000] {standard_task_runner.py:72} INFO - Started process 1081 to run task
[2025-04-20T00:11:23.614+0000] {standard_task_runner.py:104} INFO - Running: ['***', 'tasks', 'run', 'kindle_store_etl_taskflow', 'extract_review_data', 'scheduled__2025-04-13T00:00:00+00:00', '--job-id', '130', '--raw', '--subdir', 'DAGS_FOLDER/etl.py', '--cfg-path', '/tmp/tmpgnv7w_rt']
[2025-04-20T00:11:23.614+0000] {standard_task_runner.py:105} INFO - Job 130: Subtask extract_review_data
[2025-04-20T00:11:23.645+0000] {task_command.py:467} INFO - Running <TaskInstance: kindle_store_etl_taskflow.extract_review_data scheduled__2025-04-13T00:00:00+00:00 [running]> on host 6de313ec70ae
[2025-04-20T00:11:23.687+0000] {taskinstance.py:3134} INFO - Exporting env vars: AIRFLOW_CTX_DAG_OWNER='***' AIRFLOW_CTX_DAG_ID='kindle_store_etl_taskflow' AIRFLOW_CTX_TASK_ID='extract_review_data' AIRFLOW_CTX_EXECUTION_DATE='2025-04-13T00:00:00+00:00' AIRFLOW_CTX_TRY_NUMBER='1' AIRFLOW_CTX_DAG_RUN_ID='scheduled__2025-04-13T00:00:00+00:00'
[2025-04-20T00:11:23.688+0000] {logging_mixin.py:190} INFO - Task instance is in running state
[2025-04-20T00:11:23.689+0000] {logging_mixin.py:190} INFO -  Previous state of the Task instance: queued
[2025-04-20T00:11:23.689+0000] {logging_mixin.py:190} INFO - Current task name:extract_review_data state:running start_date:2025-04-20 00:11:23.598781+00:00
[2025-04-20T00:11:23.689+0000] {logging_mixin.py:190} INFO - Dag name:kindle_store_etl_taskflow and current dag run status:running
[2025-04-20T00:11:23.690+0000] {taskinstance.py:732} INFO - ::endgroup::
[2025-04-20T00:11:23.690+0000] {logging_mixin.py:190} INFO - False
[2025-04-20T00:11:41.204+0000] {log.py:232} WARNING - Error while downloading from https://cdn-lfs-us-1.hf.co/repos/e9/40/e940a8d106b2e3986d1f8b7626c5a3f4fced3c1f43b992d12b1d465b58efc824/82024e17fdd988f47d8b5ae679643965255ae5164f9f494d6ba28ab9cc0efa76?response-content-disposition=inline%3B+filename*%3DUTF-8%27%27Kindle_Store.jsonl%3B+filename%3D%22Kindle_Store.jsonl%22%3B&Expires=1745112024&Policy=eyJTdGF0ZW1lbnQiOlt7IkNvbmRpdGlvbiI6eyJEYXRlTGVzc1RoYW4iOnsiQVdTOkVwb2NoVGltZSI6MTc0NTExMjAyNH19LCJSZXNvdXJjZSI6Imh0dHBzOi8vY2RuLWxmcy11cy0xLmhmLmNvL3JlcG9zL2U5LzQwL2U5NDBhOGQxMDZiMmUzOTg2ZDFmOGI3NjI2YzVhM2Y0ZmNlZDNjMWY0M2I5OTJkMTJiMWQ0NjViNThlZmM4MjQvODIwMjRlMTdmZGQ5ODhmNDdkOGI1YWU2Nzk2NDM5NjUyNTVhZTUxNjRmOWY0OTRkNmJhMjhhYjljYzBlZmE3Nj9yZXNwb25zZS1jb250ZW50LWRpc3Bvc2l0aW9uPSoifV19&Signature=UWoQgmhxEMvSQhFak3bl8H7cGDXgy%7EBK51wPqucmvnekyNahkT5WN6I07hX93UHmgogUarwdfB6Bl3Eqg%7ExTKU-TWlER-yZKGHQ3sZDBExPSlXRtHfN-Nmj6cZbNhuHGLEa-v8nGAB98H7twfKEAKjFuSxRBlp0%7E39a-5yMyl6PUVPZ9PFQfJ76z17xcNijmiMEOwUSLUUXIEDXQoLQIKqCAZYVosLchyNA8KjlzWGeTOflr6sUB4rg4z9lgh7ESa-4JE3evLLaQFIjAmgI1Ba59SHolouZYgWsAnNKt-ZSE8Od4zGb9K31qhzUvfWrst0eBLRHXZ6HZUZ-MoTX3ww__&Key-Pair-Id=K24J24Z295AEI9: HTTPSConnectionPool(host='cdn-lfs-us-1.hf.co', port=443): Read timed out.
Trying to resume download...
[2025-04-20T00:11:41.202+0000] {file_download.py:463} WARNING - Error while downloading from https://cdn-lfs-us-1.hf.co/repos/e9/40/e940a8d106b2e3986d1f8b7626c5a3f4fced3c1f43b992d12b1d465b58efc824/82024e17fdd988f47d8b5ae679643965255ae5164f9f494d6ba28ab9cc0efa76?response-content-disposition=inline%3B+filename*%3DUTF-8%27%27Kindle_Store.jsonl%3B+filename%3D%22Kindle_Store.jsonl%22%3B&Expires=1745112024&Policy=eyJTdGF0ZW1lbnQiOlt7IkNvbmRpdGlvbiI6eyJEYXRlTGVzc1RoYW4iOnsiQVdTOkVwb2NoVGltZSI6MTc0NTExMjAyNH19LCJSZXNvdXJjZSI6Imh0dHBzOi8vY2RuLWxmcy11cy0xLmhmLmNvL3JlcG9zL2U5LzQwL2U5NDBhOGQxMDZiMmUzOTg2ZDFmOGI3NjI2YzVhM2Y0ZmNlZDNjMWY0M2I5OTJkMTJiMWQ0NjViNThlZmM4MjQvODIwMjRlMTdmZGQ5ODhmNDdkOGI1YWU2Nzk2NDM5NjUyNTVhZTUxNjRmOWY0OTRkNmJhMjhhYjljYzBlZmE3Nj9yZXNwb25zZS1jb250ZW50LWRpc3Bvc2l0aW9uPSoifV19&Signature=UWoQgmhxEMvSQhFak3bl8H7cGDXgy%7EBK51wPqucmvnekyNahkT5WN6I07hX93UHmgogUarwdfB6Bl3Eqg%7ExTKU-TWlER-yZKGHQ3sZDBExPSlXRtHfN-Nmj6cZbNhuHGLEa-v8nGAB98H7twfKEAKjFuSxRBlp0%7E39a-5yMyl6PUVPZ9PFQfJ76z17xcNijmiMEOwUSLUUXIEDXQoLQIKqCAZYVosLchyNA8KjlzWGeTOflr6sUB4rg4z9lgh7ESa-4JE3evLLaQFIjAmgI1Ba59SHolouZYgWsAnNKt-ZSE8Od4zGb9K31qhzUvfWrst0eBLRHXZ6HZUZ-MoTX3ww__&Key-Pair-Id=K24J24Z295AEI9: HTTPSConnectionPool(host='cdn-lfs-us-1.hf.co', port=443): Read timed out.
Trying to resume download...
[2025-04-20T01:21:27.963+0000] {job.py:229} INFO - Heartbeat recovered after 4179.04 seconds
[2025-04-20T01:21:31.360+0000] {log.py:232} WARNING - Error while downloading from https://cdn-lfs-us-1.hf.co/repos/e9/40/e940a8d106b2e3986d1f8b7626c5a3f4fced3c1f43b992d12b1d465b58efc824/82024e17fdd988f47d8b5ae679643965255ae5164f9f494d6ba28ab9cc0efa76?response-content-disposition=inline%3B+filename*%3DUTF-8%27%27Kindle_Store.jsonl%3B+filename%3D%22Kindle_Store.jsonl%22%3B&Expires=1745112024&Policy=eyJTdGF0ZW1lbnQiOlt7IkNvbmRpdGlvbiI6eyJEYXRlTGVzc1RoYW4iOnsiQVdTOkVwb2NoVGltZSI6MTc0NTExMjAyNH19LCJSZXNvdXJjZSI6Imh0dHBzOi8vY2RuLWxmcy11cy0xLmhmLmNvL3JlcG9zL2U5LzQwL2U5NDBhOGQxMDZiMmUzOTg2ZDFmOGI3NjI2YzVhM2Y0ZmNlZDNjMWY0M2I5OTJkMTJiMWQ0NjViNThlZmM4MjQvODIwMjRlMTdmZGQ5ODhmNDdkOGI1YWU2Nzk2NDM5NjUyNTVhZTUxNjRmOWY0OTRkNmJhMjhhYjljYzBlZmE3Nj9yZXNwb25zZS1jb250ZW50LWRpc3Bvc2l0aW9uPSoifV19&Signature=UWoQgmhxEMvSQhFak3bl8H7cGDXgy%7EBK51wPqucmvnekyNahkT5WN6I07hX93UHmgogUarwdfB6Bl3Eqg%7ExTKU-TWlER-yZKGHQ3sZDBExPSlXRtHfN-Nmj6cZbNhuHGLEa-v8nGAB98H7twfKEAKjFuSxRBlp0%7E39a-5yMyl6PUVPZ9PFQfJ76z17xcNijmiMEOwUSLUUXIEDXQoLQIKqCAZYVosLchyNA8KjlzWGeTOflr6sUB4rg4z9lgh7ESa-4JE3evLLaQFIjAmgI1Ba59SHolouZYgWsAnNKt-ZSE8Od4zGb9K31qhzUvfWrst0eBLRHXZ6HZUZ-MoTX3ww__&Key-Pair-Id=K24J24Z295AEI9: HTTPSConnectionPool(host='cdn-lfs-us-1.hf.co', port=443): Read timed out.
Trying to resume download...
[2025-04-20T01:21:31.359+0000] {file_download.py:463} WARNING - Error while downloading from https://cdn-lfs-us-1.hf.co/repos/e9/40/e940a8d106b2e3986d1f8b7626c5a3f4fced3c1f43b992d12b1d465b58efc824/82024e17fdd988f47d8b5ae679643965255ae5164f9f494d6ba28ab9cc0efa76?response-content-disposition=inline%3B+filename*%3DUTF-8%27%27Kindle_Store.jsonl%3B+filename%3D%22Kindle_Store.jsonl%22%3B&Expires=1745112024&Policy=eyJTdGF0ZW1lbnQiOlt7IkNvbmRpdGlvbiI6eyJEYXRlTGVzc1RoYW4iOnsiQVdTOkVwb2NoVGltZSI6MTc0NTExMjAyNH19LCJSZXNvdXJjZSI6Imh0dHBzOi8vY2RuLWxmcy11cy0xLmhmLmNvL3JlcG9zL2U5LzQwL2U5NDBhOGQxMDZiMmUzOTg2ZDFmOGI3NjI2YzVhM2Y0ZmNlZDNjMWY0M2I5OTJkMTJiMWQ0NjViNThlZmM4MjQvODIwMjRlMTdmZGQ5ODhmNDdkOGI1YWU2Nzk2NDM5NjUyNTVhZTUxNjRmOWY0OTRkNmJhMjhhYjljYzBlZmE3Nj9yZXNwb25zZS1jb250ZW50LWRpc3Bvc2l0aW9uPSoifV19&Signature=UWoQgmhxEMvSQhFak3bl8H7cGDXgy%7EBK51wPqucmvnekyNahkT5WN6I07hX93UHmgogUarwdfB6Bl3Eqg%7ExTKU-TWlER-yZKGHQ3sZDBExPSlXRtHfN-Nmj6cZbNhuHGLEa-v8nGAB98H7twfKEAKjFuSxRBlp0%7E39a-5yMyl6PUVPZ9PFQfJ76z17xcNijmiMEOwUSLUUXIEDXQoLQIKqCAZYVosLchyNA8KjlzWGeTOflr6sUB4rg4z9lgh7ESa-4JE3evLLaQFIjAmgI1Ba59SHolouZYgWsAnNKt-ZSE8Od4zGb9K31qhzUvfWrst0eBLRHXZ6HZUZ-MoTX3ww__&Key-Pair-Id=K24J24Z295AEI9: HTTPSConnectionPool(host='cdn-lfs-us-1.hf.co', port=443): Read timed out.
Trying to resume download...
[2025-04-20T01:21:32.438+0000] {taskinstance.py:3313} ERROR - Task failed with exception
Traceback (most recent call last):
  File "/home/airflow/.local/lib/python3.12/site-packages/urllib3/response.py", line 754, in _error_catcher
    yield
  File "/home/airflow/.local/lib/python3.12/site-packages/urllib3/response.py", line 879, in _raw_read
    data = self._fp_read(amt, read1=read1) if not fp_closed else b""
           ^^^^^^^^^^^^^^^^^^^^^^^^^^^^^^^
  File "/home/airflow/.local/lib/python3.12/site-packages/urllib3/response.py", line 862, in _fp_read
    return self._fp.read(amt) if amt is not None else self._fp.read()
           ^^^^^^^^^^^^^^^^^^
  File "/usr/local/lib/python3.12/http/client.py", line 479, in read
    s = self.fp.read(amt)
        ^^^^^^^^^^^^^^^^^
  File "/usr/local/lib/python3.12/socket.py", line 720, in readinto
    return self._sock.recv_into(b)
           ^^^^^^^^^^^^^^^^^^^^^^^
  File "/usr/local/lib/python3.12/ssl.py", line 1251, in recv_into
    return self.read(nbytes, buffer)
           ^^^^^^^^^^^^^^^^^^^^^^^^^
  File "/usr/local/lib/python3.12/ssl.py", line 1103, in read
    return self._sslobj.read(len, buffer)
           ^^^^^^^^^^^^^^^^^^^^^^^^^^^^^^
TimeoutError: The read operation timed out

The above exception was the direct cause of the following exception:

Traceback (most recent call last):
  File "/home/airflow/.local/lib/python3.12/site-packages/requests/models.py", line 820, in generate
    yield from self.raw.stream(chunk_size, decode_content=True)
  File "/home/airflow/.local/lib/python3.12/site-packages/urllib3/response.py", line 1066, in stream
    data = self.read(amt=amt, decode_content=decode_content)
           ^^^^^^^^^^^^^^^^^^^^^^^^^^^^^^^^^^^^^^^^^^^^^^^^^
  File "/home/airflow/.local/lib/python3.12/site-packages/urllib3/response.py", line 955, in read
    data = self._raw_read(amt)
           ^^^^^^^^^^^^^^^^^^^
  File "/home/airflow/.local/lib/python3.12/site-packages/urllib3/response.py", line 878, in _raw_read
    with self._error_catcher():
         ^^^^^^^^^^^^^^^^^^^^^
  File "/usr/local/lib/python3.12/contextlib.py", line 158, in __exit__
    self.gen.throw(value)
  File "/home/airflow/.local/lib/python3.12/site-packages/urllib3/response.py", line 759, in _error_catcher
    raise ReadTimeoutError(self._pool, None, "Read timed out.") from e  # type: ignore[arg-type]
    ^^^^^^^^^^^^^^^^^^^^^^^^^^^^^^^^^^^^^^^^^^^^^^^^^^^^^^^^^^^^^^^^^^
urllib3.exceptions.ReadTimeoutError: HTTPSConnectionPool(host='cdn-lfs-us-1.hf.co', port=443): Read timed out.

During handling of the above exception, another exception occurred:

Traceback (most recent call last):
  File "/home/airflow/.local/lib/python3.12/site-packages/huggingface_hub/file_download.py", line 449, in http_get
    for chunk in r.iter_content(chunk_size=constants.DOWNLOAD_CHUNK_SIZE):
                 ^^^^^^^^^^^^^^^^^^^^^^^^^^^^^^^^^^^^^^^^^^^^^^^^^^^^^^^^
  File "/home/airflow/.local/lib/python3.12/site-packages/requests/models.py", line 826, in generate
    raise ConnectionError(e)
requests.exceptions.ConnectionError: HTTPSConnectionPool(host='cdn-lfs-us-1.hf.co', port=443): Read timed out.

During handling of the above exception, another exception occurred:

Traceback (most recent call last):
  File "/home/airflow/.local/lib/python3.12/site-packages/urllib3/response.py", line 754, in _error_catcher
    yield
  File "/home/airflow/.local/lib/python3.12/site-packages/urllib3/response.py", line 879, in _raw_read
    data = self._fp_read(amt, read1=read1) if not fp_closed else b""
           ^^^^^^^^^^^^^^^^^^^^^^^^^^^^^^^
  File "/home/airflow/.local/lib/python3.12/site-packages/urllib3/response.py", line 862, in _fp_read
    return self._fp.read(amt) if amt is not None else self._fp.read()
           ^^^^^^^^^^^^^^^^^^
  File "/usr/local/lib/python3.12/http/client.py", line 479, in read
    s = self.fp.read(amt)
        ^^^^^^^^^^^^^^^^^
  File "/usr/local/lib/python3.12/socket.py", line 720, in readinto
    return self._sock.recv_into(b)
           ^^^^^^^^^^^^^^^^^^^^^^^
  File "/usr/local/lib/python3.12/ssl.py", line 1251, in recv_into
    return self.read(nbytes, buffer)
           ^^^^^^^^^^^^^^^^^^^^^^^^^
  File "/usr/local/lib/python3.12/ssl.py", line 1103, in read
    return self._sslobj.read(len, buffer)
           ^^^^^^^^^^^^^^^^^^^^^^^^^^^^^^
TimeoutError: The read operation timed out

The above exception was the direct cause of the following exception:

Traceback (most recent call last):
  File "/home/airflow/.local/lib/python3.12/site-packages/requests/models.py", line 820, in generate
    yield from self.raw.stream(chunk_size, decode_content=True)
  File "/home/airflow/.local/lib/python3.12/site-packages/urllib3/response.py", line 1066, in stream
    data = self.read(amt=amt, decode_content=decode_content)
           ^^^^^^^^^^^^^^^^^^^^^^^^^^^^^^^^^^^^^^^^^^^^^^^^^
  File "/home/airflow/.local/lib/python3.12/site-packages/urllib3/response.py", line 955, in read
    data = self._raw_read(amt)
           ^^^^^^^^^^^^^^^^^^^
  File "/home/airflow/.local/lib/python3.12/site-packages/urllib3/response.py", line 878, in _raw_read
    with self._error_catcher():
         ^^^^^^^^^^^^^^^^^^^^^
  File "/usr/local/lib/python3.12/contextlib.py", line 158, in __exit__
    self.gen.throw(value)
  File "/home/airflow/.local/lib/python3.12/site-packages/urllib3/response.py", line 759, in _error_catcher
    raise ReadTimeoutError(self._pool, None, "Read timed out.") from e  # type: ignore[arg-type]
    ^^^^^^^^^^^^^^^^^^^^^^^^^^^^^^^^^^^^^^^^^^^^^^^^^^^^^^^^^^^^^^^^^^
urllib3.exceptions.ReadTimeoutError: HTTPSConnectionPool(host='cdn-lfs-us-1.hf.co', port=443): Read timed out.

During handling of the above exception, another exception occurred:

Traceback (most recent call last):
  File "/home/airflow/.local/lib/python3.12/site-packages/huggingface_hub/file_download.py", line 449, in http_get
    for chunk in r.iter_content(chunk_size=constants.DOWNLOAD_CHUNK_SIZE):
                 ^^^^^^^^^^^^^^^^^^^^^^^^^^^^^^^^^^^^^^^^^^^^^^^^^^^^^^^^
  File "/home/airflow/.local/lib/python3.12/site-packages/requests/models.py", line 826, in generate
    raise ConnectionError(e)
requests.exceptions.ConnectionError: HTTPSConnectionPool(host='cdn-lfs-us-1.hf.co', port=443): Read timed out.

During handling of the above exception, another exception occurred:

Traceback (most recent call last):
  File "/home/airflow/.local/lib/python3.12/site-packages/huggingface_hub/utils/_http.py", line 409, in hf_raise_for_status
    response.raise_for_status()
  File "/home/airflow/.local/lib/python3.12/site-packages/requests/models.py", line 1024, in raise_for_status
    raise HTTPError(http_error_msg, response=self)
requests.exceptions.HTTPError: 403 Client Error: Forbidden for url: https://cdn-lfs-us-1.hf.co/repos/e9/40/e940a8d106b2e3986d1f8b7626c5a3f4fced3c1f43b992d12b1d465b58efc824/82024e17fdd988f47d8b5ae679643965255ae5164f9f494d6ba28ab9cc0efa76?response-content-disposition=inline%3B+filename*%3DUTF-8%27%27Kindle_Store.jsonl%3B+filename%3D%22Kindle_Store.jsonl%22%3B&Expires=1745112024&Policy=eyJTdGF0ZW1lbnQiOlt7IkNvbmRpdGlvbiI6eyJEYXRlTGVzc1RoYW4iOnsiQVdTOkVwb2NoVGltZSI6MTc0NTExMjAyNH19LCJSZXNvdXJjZSI6Imh0dHBzOi8vY2RuLWxmcy11cy0xLmhmLmNvL3JlcG9zL2U5LzQwL2U5NDBhOGQxMDZiMmUzOTg2ZDFmOGI3NjI2YzVhM2Y0ZmNlZDNjMWY0M2I5OTJkMTJiMWQ0NjViNThlZmM4MjQvODIwMjRlMTdmZGQ5ODhmNDdkOGI1YWU2Nzk2NDM5NjUyNTVhZTUxNjRmOWY0OTRkNmJhMjhhYjljYzBlZmE3Nj9yZXNwb25zZS1jb250ZW50LWRpc3Bvc2l0aW9uPSoifV19&Signature=UWoQgmhxEMvSQhFak3bl8H7cGDXgy~BK51wPqucmvnekyNahkT5WN6I07hX93UHmgogUarwdfB6Bl3Eqg~xTKU-TWlER-yZKGHQ3sZDBExPSlXRtHfN-Nmj6cZbNhuHGLEa-v8nGAB98H7twfKEAKjFuSxRBlp0~39a-5yMyl6PUVPZ9PFQfJ76z17xcNijmiMEOwUSLUUXIEDXQoLQIKqCAZYVosLchyNA8KjlzWGeTOflr6sUB4rg4z9lgh7ESa-4JE3evLLaQFIjAmgI1Ba59SHolouZYgWsAnNKt-ZSE8Od4zGb9K31qhzUvfWrst0eBLRHXZ6HZUZ-MoTX3ww__&Key-Pair-Id=K24J24Z295AEI9

The above exception was the direct cause of the following exception:

Traceback (most recent call last):
  File "/home/airflow/.local/lib/python3.12/site-packages/airflow/models/taskinstance.py", line 768, in _execute_task
    result = _execute_callable(context=context, **execute_callable_kwargs)
             ^^^^^^^^^^^^^^^^^^^^^^^^^^^^^^^^^^^^^^^^^^^^^^^^^^^^^^^^^^^^^
  File "/home/airflow/.local/lib/python3.12/site-packages/airflow/models/taskinstance.py", line 734, in _execute_callable
    return ExecutionCallableRunner(
           ^^^^^^^^^^^^^^^^^^^^^^^^
  File "/home/airflow/.local/lib/python3.12/site-packages/airflow/utils/operator_helpers.py", line 252, in run
    return self.func(*args, **kwargs)
           ^^^^^^^^^^^^^^^^^^^^^^^^^^
  File "/home/airflow/.local/lib/python3.12/site-packages/airflow/models/baseoperator.py", line 424, in wrapper
    return func(self, *args, **kwargs)
           ^^^^^^^^^^^^^^^^^^^^^^^^^^^
  File "/home/airflow/.local/lib/python3.12/site-packages/airflow/decorators/base.py", line 266, in execute
    return_value = super().execute(context)
                   ^^^^^^^^^^^^^^^^^^^^^^^^
  File "/home/airflow/.local/lib/python3.12/site-packages/airflow/models/baseoperator.py", line 424, in wrapper
    return func(self, *args, **kwargs)
           ^^^^^^^^^^^^^^^^^^^^^^^^^^^
  File "/home/airflow/.local/lib/python3.12/site-packages/airflow/operators/python.py", line 238, in execute
    return_value = self.execute_callable()
                   ^^^^^^^^^^^^^^^^^^^^^^^
  File "/home/airflow/.local/lib/python3.12/site-packages/airflow/operators/python.py", line 256, in execute_callable
    return runner.run(*self.op_args, **self.op_kwargs)
           ^^^^^^^^^^^^^^^^^^^^^^^^^^^^^^^^^^^^^^^^^^^
  File "/home/airflow/.local/lib/python3.12/site-packages/airflow/utils/operator_helpers.py", line 252, in run
    return self.func(*args, **kwargs)
           ^^^^^^^^^^^^^^^^^^^^^^^^^^
  File "/opt/airflow/dags/etl.py", line 64, in extract_review_data
    reviews_dataset = load_dataset("McAuley-Lab/Amazon-Reviews-2023", "raw_review_Kindle_Store", trust_remote_code=True,num_proc=64,split = 'full')
                      ^^^^^^^^^^^^^^^^^^^^^^^^^^^^^^^^^^^^^^^^^^^^^^^^^^^^^^^^^^^^^^^^^^^^^^^^^^^^^^^^^^^^^^^^^^^^^^^^^^^^^^^^^^^^^^^^^^^^^^^^^^^^^
  File "/home/airflow/.local/lib/python3.12/site-packages/datasets/load.py", line 2084, in load_dataset
    builder_instance.download_and_prepare(
  File "/home/airflow/.local/lib/python3.12/site-packages/datasets/builder.py", line 925, in download_and_prepare
    self._download_and_prepare(
  File "/home/airflow/.local/lib/python3.12/site-packages/datasets/builder.py", line 1649, in _download_and_prepare
    super()._download_and_prepare(
  File "/home/airflow/.local/lib/python3.12/site-packages/datasets/builder.py", line 979, in _download_and_prepare
    split_generators = self._split_generators(dl_manager, **split_generators_kwargs)
                       ^^^^^^^^^^^^^^^^^^^^^^^^^^^^^^^^^^^^^^^^^^^^^^^^^^^^^^^^^^^^^
  File "/home/airflow/.cache/huggingface/modules/datasets_modules/datasets/McAuley-Lab--Amazon-Reviews-2023/16b76e0823d73bb8cff1e9c5e3e37dbc46ae3daee380417ae141f5e67d3ea8e8/Amazon-Reviews-2023.py", line 509, in _split_generators
    dl_dir = dl_manager.download_and_extract(self.config.data_dir)
             ^^^^^^^^^^^^^^^^^^^^^^^^^^^^^^^^^^^^^^^^^^^^^^^^^^^^^
  File "/home/airflow/.local/lib/python3.12/site-packages/datasets/download/download_manager.py", line 326, in download_and_extract
    return self.extract(self.download(url_or_urls))
                        ^^^^^^^^^^^^^^^^^^^^^^^^^^
  File "/home/airflow/.local/lib/python3.12/site-packages/datasets/download/download_manager.py", line 159, in download
    downloaded_path_or_paths = map_nested(
                               ^^^^^^^^^^^
  File "/home/airflow/.local/lib/python3.12/site-packages/datasets/utils/py_utils.py", line 486, in map_nested
    mapped = function(data_struct)
             ^^^^^^^^^^^^^^^^^^^^^
  File "/home/airflow/.local/lib/python3.12/site-packages/datasets/download/download_manager.py", line 220, in _download_batched
    self._download_single(url_or_filename, download_config=download_config)
  File "/home/airflow/.local/lib/python3.12/site-packages/datasets/download/download_manager.py", line 229, in _download_single
    out = cached_path(url_or_filename, download_config=download_config)
          ^^^^^^^^^^^^^^^^^^^^^^^^^^^^^^^^^^^^^^^^^^^^^^^^^^^^^^^^^^^^^
  File "/home/airflow/.local/lib/python3.12/site-packages/datasets/utils/file_utils.py", line 189, in cached_path
    ).hf_hub_download(
      ^^^^^^^^^^^^^^^^
  File "/home/airflow/.local/lib/python3.12/site-packages/huggingface_hub/utils/_validators.py", line 114, in _inner_fn
    return fn(*args, **kwargs)
           ^^^^^^^^^^^^^^^^^^^
  File "/home/airflow/.local/lib/python3.12/site-packages/huggingface_hub/hf_api.py", line 5475, in hf_hub_download
    return hf_hub_download(
           ^^^^^^^^^^^^^^^^
  File "/home/airflow/.local/lib/python3.12/site-packages/huggingface_hub/utils/_validators.py", line 114, in _inner_fn
    return fn(*args, **kwargs)
           ^^^^^^^^^^^^^^^^^^^
  File "/home/airflow/.local/lib/python3.12/site-packages/huggingface_hub/file_download.py", line 961, in hf_hub_download
    return _hf_hub_download_to_cache_dir(
           ^^^^^^^^^^^^^^^^^^^^^^^^^^^^^^
  File "/home/airflow/.local/lib/python3.12/site-packages/huggingface_hub/file_download.py", line 1112, in _hf_hub_download_to_cache_dir
    _download_to_tmp_and_move(
  File "/home/airflow/.local/lib/python3.12/site-packages/huggingface_hub/file_download.py", line 1675, in _download_to_tmp_and_move
    http_get(
  File "/home/airflow/.local/lib/python3.12/site-packages/huggingface_hub/file_download.py", line 466, in http_get
    return http_get(
           ^^^^^^^^^
  File "/home/airflow/.local/lib/python3.12/site-packages/huggingface_hub/file_download.py", line 466, in http_get
    return http_get(
           ^^^^^^^^^
  File "/home/airflow/.local/lib/python3.12/site-packages/huggingface_hub/file_download.py", line 376, in http_get
    r = _request_wrapper(
        ^^^^^^^^^^^^^^^^^
  File "/home/airflow/.local/lib/python3.12/site-packages/huggingface_hub/file_download.py", line 309, in _request_wrapper
    hf_raise_for_status(response)
  File "/home/airflow/.local/lib/python3.12/site-packages/huggingface_hub/utils/_http.py", line 473, in hf_raise_for_status
    raise _format(HfHubHTTPError, message, response) from e
huggingface_hub.errors.HfHubHTTPError: 403 Forbidden: None.
Cannot access content at: https://cdn-lfs-us-1.hf.co/repos/e9/40/e940a8d106b2e3986d1f8b7626c5a3f4fced3c1f43b992d12b1d465b58efc824/82024e17fdd988f47d8b5ae679643965255ae5164f9f494d6ba28ab9cc0efa76?response-content-disposition=inline%3B+filename*%3DUTF-8%27%27Kindle_Store.jsonl%3B+filename%3D%22Kindle_Store.jsonl%22%3B&Expires=1745112024&Policy=eyJTdGF0ZW1lbnQiOlt7IkNvbmRpdGlvbiI6eyJEYXRlTGVzc1RoYW4iOnsiQVdTOkVwb2NoVGltZSI6MTc0NTExMjAyNH19LCJSZXNvdXJjZSI6Imh0dHBzOi8vY2RuLWxmcy11cy0xLmhmLmNvL3JlcG9zL2U5LzQwL2U5NDBhOGQxMDZiMmUzOTg2ZDFmOGI3NjI2YzVhM2Y0ZmNlZDNjMWY0M2I5OTJkMTJiMWQ0NjViNThlZmM4MjQvODIwMjRlMTdmZGQ5ODhmNDdkOGI1YWU2Nzk2NDM5NjUyNTVhZTUxNjRmOWY0OTRkNmJhMjhhYjljYzBlZmE3Nj9yZXNwb25zZS1jb250ZW50LWRpc3Bvc2l0aW9uPSoifV19&Signature=UWoQgmhxEMvSQhFak3bl8H7cGDXgy~BK51wPqucmvnekyNahkT5WN6I07hX93UHmgogUarwdfB6Bl3Eqg~xTKU-TWlER-yZKGHQ3sZDBExPSlXRtHfN-Nmj6cZbNhuHGLEa-v8nGAB98H7twfKEAKjFuSxRBlp0~39a-5yMyl6PUVPZ9PFQfJ76z17xcNijmiMEOwUSLUUXIEDXQoLQIKqCAZYVosLchyNA8KjlzWGeTOflr6sUB4rg4z9lgh7ESa-4JE3evLLaQFIjAmgI1Ba59SHolouZYgWsAnNKt-ZSE8Od4zGb9K31qhzUvfWrst0eBLRHXZ6HZUZ-MoTX3ww__&Key-Pair-Id=K24J24Z295AEI9.
Make sure your token has the correct permissions.
<?xml version="1.0" encoding="UTF-8"?><Error><Code>AccessDenied</Code><Message>Access denied</Message></Error>
[2025-04-20T01:21:32.475+0000] {logging_mixin.py:190} INFO - Task instance in failure state
[2025-04-20T01:21:32.475+0000] {logging_mixin.py:190} INFO - Task start:2025-04-20 00:11:23.598781+00:00 end:2025-04-20 01:21:32.474614+00:00 duration:4208.875833
[2025-04-20T01:21:32.475+0000] {logging_mixin.py:190} INFO - Task:<Task(_PythonDecoratedOperator): extract_review_data> dag:<DAG: kindle_store_etl_taskflow> dagrun:<DagRun kindle_store_etl_taskflow @ 2025-04-13 00:00:00+00:00: scheduled__2025-04-13T00:00:00+00:00, state:running, queued_at: 2025-04-20 00:11:20.916658+00:00. externally triggered: False>
[2025-04-20T01:21:32.476+0000] {logging_mixin.py:190} INFO - Failure caused by 403 Forbidden: None.
Cannot access content at: https://cdn-lfs-us-1.hf.co/repos/e9/40/e940a8d106b2e3986d1f8b7626c5a3f4fced3c1f43b992d12b1d465b58efc824/82024e17fdd988f47d8b5ae679643965255ae5164f9f494d6ba28ab9cc0efa76?response-content-disposition=inline%3B+filename*%3DUTF-8%27%27Kindle_Store.jsonl%3B+filename%3D%22Kindle_Store.jsonl%22%3B&Expires=1745112024&Policy=eyJTdGF0ZW1lbnQiOlt7IkNvbmRpdGlvbiI6eyJEYXRlTGVzc1RoYW4iOnsiQVdTOkVwb2NoVGltZSI6MTc0NTExMjAyNH19LCJSZXNvdXJjZSI6Imh0dHBzOi8vY2RuLWxmcy11cy0xLmhmLmNvL3JlcG9zL2U5LzQwL2U5NDBhOGQxMDZiMmUzOTg2ZDFmOGI3NjI2YzVhM2Y0ZmNlZDNjMWY0M2I5OTJkMTJiMWQ0NjViNThlZmM4MjQvODIwMjRlMTdmZGQ5ODhmNDdkOGI1YWU2Nzk2NDM5NjUyNTVhZTUxNjRmOWY0OTRkNmJhMjhhYjljYzBlZmE3Nj9yZXNwb25zZS1jb250ZW50LWRpc3Bvc2l0aW9uPSoifV19&Signature=UWoQgmhxEMvSQhFak3bl8H7cGDXgy~BK51wPqucmvnekyNahkT5WN6I07hX93UHmgogUarwdfB6Bl3Eqg~xTKU-TWlER-yZKGHQ3sZDBExPSlXRtHfN-Nmj6cZbNhuHGLEa-v8nGAB98H7twfKEAKjFuSxRBlp0~39a-5yMyl6PUVPZ9PFQfJ76z17xcNijmiMEOwUSLUUXIEDXQoLQIKqCAZYVosLchyNA8KjlzWGeTOflr6sUB4rg4z9lgh7ESa-4JE3evLLaQFIjAmgI1Ba59SHolouZYgWsAnNKt-ZSE8Od4zGb9K31qhzUvfWrst0eBLRHXZ6HZUZ-MoTX3ww__&Key-Pair-Id=K24J24Z295AEI9.
Make sure your token has the correct permissions.
<?xml version="1.0" encoding="UTF-8"?><Error><Code>AccessDenied</Code><Message>Access denied</Message></Error>
[2025-04-20T01:21:32.476+0000] {taskinstance.py:1226} INFO - Marking task as FAILED. dag_id=kindle_store_etl_taskflow, task_id=extract_review_data, run_id=scheduled__2025-04-13T00:00:00+00:00, execution_date=20250413T000000, start_date=20250420T001123, end_date=20250420T012132
[2025-04-20T01:21:32.491+0000] {taskinstance.py:341} INFO - ::group::Post task execution logs
[2025-04-20T01:21:32.491+0000] {standard_task_runner.py:124} ERROR - Failed to execute job 130 for task extract_review_data (403 Forbidden: None.
Cannot access content at: https://cdn-lfs-us-1.hf.co/repos/e9/40/e940a8d106b2e3986d1f8b7626c5a3f4fced3c1f43b992d12b1d465b58efc824/82024e17fdd988f47d8b5ae679643965255ae5164f9f494d6ba28ab9cc0efa76?response-content-disposition=inline%3B+filename*%3DUTF-8%27%27Kindle_Store.jsonl%3B+filename%3D%22Kindle_Store.jsonl%22%3B&Expires=1745112024&Policy=eyJTdGF0ZW1lbnQiOlt7IkNvbmRpdGlvbiI6eyJEYXRlTGVzc1RoYW4iOnsiQVdTOkVwb2NoVGltZSI6MTc0NTExMjAyNH19LCJSZXNvdXJjZSI6Imh0dHBzOi8vY2RuLWxmcy11cy0xLmhmLmNvL3JlcG9zL2U5LzQwL2U5NDBhOGQxMDZiMmUzOTg2ZDFmOGI3NjI2YzVhM2Y0ZmNlZDNjMWY0M2I5OTJkMTJiMWQ0NjViNThlZmM4MjQvODIwMjRlMTdmZGQ5ODhmNDdkOGI1YWU2Nzk2NDM5NjUyNTVhZTUxNjRmOWY0OTRkNmJhMjhhYjljYzBlZmE3Nj9yZXNwb25zZS1jb250ZW50LWRpc3Bvc2l0aW9uPSoifV19&Signature=UWoQgmhxEMvSQhFak3bl8H7cGDXgy~BK51wPqucmvnekyNahkT5WN6I07hX93UHmgogUarwdfB6Bl3Eqg~xTKU-TWlER-yZKGHQ3sZDBExPSlXRtHfN-Nmj6cZbNhuHGLEa-v8nGAB98H7twfKEAKjFuSxRBlp0~39a-5yMyl6PUVPZ9PFQfJ76z17xcNijmiMEOwUSLUUXIEDXQoLQIKqCAZYVosLchyNA8KjlzWGeTOflr6sUB4rg4z9lgh7ESa-4JE3evLLaQFIjAmgI1Ba59SHolouZYgWsAnNKt-ZSE8Od4zGb9K31qhzUvfWrst0eBLRHXZ6HZUZ-MoTX3ww__&Key-Pair-Id=K24J24Z295AEI9.
Make sure your token has the correct permissions.
<?xml version="1.0" encoding="UTF-8"?><Error><Code>AccessDenied</Code><Message>Access denied</Message></Error>; 1081)
Traceback (most recent call last):
  File "/home/airflow/.local/lib/python3.12/site-packages/urllib3/response.py", line 754, in _error_catcher
    yield
  File "/home/airflow/.local/lib/python3.12/site-packages/urllib3/response.py", line 879, in _raw_read
    data = self._fp_read(amt, read1=read1) if not fp_closed else b""
           ^^^^^^^^^^^^^^^^^^^^^^^^^^^^^^^
  File "/home/airflow/.local/lib/python3.12/site-packages/urllib3/response.py", line 862, in _fp_read
    return self._fp.read(amt) if amt is not None else self._fp.read()
           ^^^^^^^^^^^^^^^^^^
  File "/usr/local/lib/python3.12/http/client.py", line 479, in read
    s = self.fp.read(amt)
        ^^^^^^^^^^^^^^^^^
  File "/usr/local/lib/python3.12/socket.py", line 720, in readinto
    return self._sock.recv_into(b)
           ^^^^^^^^^^^^^^^^^^^^^^^
  File "/usr/local/lib/python3.12/ssl.py", line 1251, in recv_into
    return self.read(nbytes, buffer)
           ^^^^^^^^^^^^^^^^^^^^^^^^^
  File "/usr/local/lib/python3.12/ssl.py", line 1103, in read
    return self._sslobj.read(len, buffer)
           ^^^^^^^^^^^^^^^^^^^^^^^^^^^^^^
TimeoutError: The read operation timed out

The above exception was the direct cause of the following exception:

Traceback (most recent call last):
  File "/home/airflow/.local/lib/python3.12/site-packages/requests/models.py", line 820, in generate
    yield from self.raw.stream(chunk_size, decode_content=True)
  File "/home/airflow/.local/lib/python3.12/site-packages/urllib3/response.py", line 1066, in stream
    data = self.read(amt=amt, decode_content=decode_content)
           ^^^^^^^^^^^^^^^^^^^^^^^^^^^^^^^^^^^^^^^^^^^^^^^^^
  File "/home/airflow/.local/lib/python3.12/site-packages/urllib3/response.py", line 955, in read
    data = self._raw_read(amt)
           ^^^^^^^^^^^^^^^^^^^
  File "/home/airflow/.local/lib/python3.12/site-packages/urllib3/response.py", line 878, in _raw_read
    with self._error_catcher():
         ^^^^^^^^^^^^^^^^^^^^^
  File "/usr/local/lib/python3.12/contextlib.py", line 158, in __exit__
    self.gen.throw(value)
  File "/home/airflow/.local/lib/python3.12/site-packages/urllib3/response.py", line 759, in _error_catcher
    raise ReadTimeoutError(self._pool, None, "Read timed out.") from e  # type: ignore[arg-type]
    ^^^^^^^^^^^^^^^^^^^^^^^^^^^^^^^^^^^^^^^^^^^^^^^^^^^^^^^^^^^^^^^^^^
urllib3.exceptions.ReadTimeoutError: HTTPSConnectionPool(host='cdn-lfs-us-1.hf.co', port=443): Read timed out.

During handling of the above exception, another exception occurred:

Traceback (most recent call last):
  File "/home/airflow/.local/lib/python3.12/site-packages/huggingface_hub/file_download.py", line 449, in http_get
    for chunk in r.iter_content(chunk_size=constants.DOWNLOAD_CHUNK_SIZE):
                 ^^^^^^^^^^^^^^^^^^^^^^^^^^^^^^^^^^^^^^^^^^^^^^^^^^^^^^^^
  File "/home/airflow/.local/lib/python3.12/site-packages/requests/models.py", line 826, in generate
    raise ConnectionError(e)
requests.exceptions.ConnectionError: HTTPSConnectionPool(host='cdn-lfs-us-1.hf.co', port=443): Read timed out.

During handling of the above exception, another exception occurred:

Traceback (most recent call last):
  File "/home/airflow/.local/lib/python3.12/site-packages/urllib3/response.py", line 754, in _error_catcher
    yield
  File "/home/airflow/.local/lib/python3.12/site-packages/urllib3/response.py", line 879, in _raw_read
    data = self._fp_read(amt, read1=read1) if not fp_closed else b""
           ^^^^^^^^^^^^^^^^^^^^^^^^^^^^^^^
  File "/home/airflow/.local/lib/python3.12/site-packages/urllib3/response.py", line 862, in _fp_read
    return self._fp.read(amt) if amt is not None else self._fp.read()
           ^^^^^^^^^^^^^^^^^^
  File "/usr/local/lib/python3.12/http/client.py", line 479, in read
    s = self.fp.read(amt)
        ^^^^^^^^^^^^^^^^^
  File "/usr/local/lib/python3.12/socket.py", line 720, in readinto
    return self._sock.recv_into(b)
           ^^^^^^^^^^^^^^^^^^^^^^^
  File "/usr/local/lib/python3.12/ssl.py", line 1251, in recv_into
    return self.read(nbytes, buffer)
           ^^^^^^^^^^^^^^^^^^^^^^^^^
  File "/usr/local/lib/python3.12/ssl.py", line 1103, in read
    return self._sslobj.read(len, buffer)
           ^^^^^^^^^^^^^^^^^^^^^^^^^^^^^^
TimeoutError: The read operation timed out

The above exception was the direct cause of the following exception:

Traceback (most recent call last):
  File "/home/airflow/.local/lib/python3.12/site-packages/requests/models.py", line 820, in generate
    yield from self.raw.stream(chunk_size, decode_content=True)
  File "/home/airflow/.local/lib/python3.12/site-packages/urllib3/response.py", line 1066, in stream
    data = self.read(amt=amt, decode_content=decode_content)
           ^^^^^^^^^^^^^^^^^^^^^^^^^^^^^^^^^^^^^^^^^^^^^^^^^
  File "/home/airflow/.local/lib/python3.12/site-packages/urllib3/response.py", line 955, in read
    data = self._raw_read(amt)
           ^^^^^^^^^^^^^^^^^^^
  File "/home/airflow/.local/lib/python3.12/site-packages/urllib3/response.py", line 878, in _raw_read
    with self._error_catcher():
         ^^^^^^^^^^^^^^^^^^^^^
  File "/usr/local/lib/python3.12/contextlib.py", line 158, in __exit__
    self.gen.throw(value)
  File "/home/airflow/.local/lib/python3.12/site-packages/urllib3/response.py", line 759, in _error_catcher
    raise ReadTimeoutError(self._pool, None, "Read timed out.") from e  # type: ignore[arg-type]
    ^^^^^^^^^^^^^^^^^^^^^^^^^^^^^^^^^^^^^^^^^^^^^^^^^^^^^^^^^^^^^^^^^^
urllib3.exceptions.ReadTimeoutError: HTTPSConnectionPool(host='cdn-lfs-us-1.hf.co', port=443): Read timed out.

During handling of the above exception, another exception occurred:

Traceback (most recent call last):
  File "/home/airflow/.local/lib/python3.12/site-packages/huggingface_hub/file_download.py", line 449, in http_get
    for chunk in r.iter_content(chunk_size=constants.DOWNLOAD_CHUNK_SIZE):
                 ^^^^^^^^^^^^^^^^^^^^^^^^^^^^^^^^^^^^^^^^^^^^^^^^^^^^^^^^
  File "/home/airflow/.local/lib/python3.12/site-packages/requests/models.py", line 826, in generate
    raise ConnectionError(e)
requests.exceptions.ConnectionError: HTTPSConnectionPool(host='cdn-lfs-us-1.hf.co', port=443): Read timed out.

During handling of the above exception, another exception occurred:

Traceback (most recent call last):
  File "/home/airflow/.local/lib/python3.12/site-packages/huggingface_hub/utils/_http.py", line 409, in hf_raise_for_status
    response.raise_for_status()
  File "/home/airflow/.local/lib/python3.12/site-packages/requests/models.py", line 1024, in raise_for_status
    raise HTTPError(http_error_msg, response=self)
requests.exceptions.HTTPError: 403 Client Error: Forbidden for url: https://cdn-lfs-us-1.hf.co/repos/e9/40/e940a8d106b2e3986d1f8b7626c5a3f4fced3c1f43b992d12b1d465b58efc824/82024e17fdd988f47d8b5ae679643965255ae5164f9f494d6ba28ab9cc0efa76?response-content-disposition=inline%3B+filename*%3DUTF-8%27%27Kindle_Store.jsonl%3B+filename%3D%22Kindle_Store.jsonl%22%3B&Expires=1745112024&Policy=eyJTdGF0ZW1lbnQiOlt7IkNvbmRpdGlvbiI6eyJEYXRlTGVzc1RoYW4iOnsiQVdTOkVwb2NoVGltZSI6MTc0NTExMjAyNH19LCJSZXNvdXJjZSI6Imh0dHBzOi8vY2RuLWxmcy11cy0xLmhmLmNvL3JlcG9zL2U5LzQwL2U5NDBhOGQxMDZiMmUzOTg2ZDFmOGI3NjI2YzVhM2Y0ZmNlZDNjMWY0M2I5OTJkMTJiMWQ0NjViNThlZmM4MjQvODIwMjRlMTdmZGQ5ODhmNDdkOGI1YWU2Nzk2NDM5NjUyNTVhZTUxNjRmOWY0OTRkNmJhMjhhYjljYzBlZmE3Nj9yZXNwb25zZS1jb250ZW50LWRpc3Bvc2l0aW9uPSoifV19&Signature=UWoQgmhxEMvSQhFak3bl8H7cGDXgy~BK51wPqucmvnekyNahkT5WN6I07hX93UHmgogUarwdfB6Bl3Eqg~xTKU-TWlER-yZKGHQ3sZDBExPSlXRtHfN-Nmj6cZbNhuHGLEa-v8nGAB98H7twfKEAKjFuSxRBlp0~39a-5yMyl6PUVPZ9PFQfJ76z17xcNijmiMEOwUSLUUXIEDXQoLQIKqCAZYVosLchyNA8KjlzWGeTOflr6sUB4rg4z9lgh7ESa-4JE3evLLaQFIjAmgI1Ba59SHolouZYgWsAnNKt-ZSE8Od4zGb9K31qhzUvfWrst0eBLRHXZ6HZUZ-MoTX3ww__&Key-Pair-Id=K24J24Z295AEI9

The above exception was the direct cause of the following exception:

Traceback (most recent call last):
  File "/home/airflow/.local/lib/python3.12/site-packages/airflow/task/task_runner/standard_task_runner.py", line 117, in _start_by_fork
    ret = args.func(args, dag=self.dag)
          ^^^^^^^^^^^^^^^^^^^^^^^^^^^^^
  File "/home/airflow/.local/lib/python3.12/site-packages/airflow/cli/cli_config.py", line 49, in command
    return func(*args, **kwargs)
           ^^^^^^^^^^^^^^^^^^^^^
  File "/home/airflow/.local/lib/python3.12/site-packages/airflow/utils/cli.py", line 116, in wrapper
    return f(*args, **kwargs)
           ^^^^^^^^^^^^^^^^^^
  File "/home/airflow/.local/lib/python3.12/site-packages/airflow/cli/commands/task_command.py", line 483, in task_run
    task_return_code = _run_task_by_selected_method(args, _dag, ti)
                       ^^^^^^^^^^^^^^^^^^^^^^^^^^^^^^^^^^^^^^^^^^^^
  File "/home/airflow/.local/lib/python3.12/site-packages/airflow/cli/commands/task_command.py", line 256, in _run_task_by_selected_method
    return _run_raw_task(args, ti)
           ^^^^^^^^^^^^^^^^^^^^^^^
  File "/home/airflow/.local/lib/python3.12/site-packages/airflow/cli/commands/task_command.py", line 341, in _run_raw_task
    return ti._run_raw_task(
           ^^^^^^^^^^^^^^^^^
  File "/home/airflow/.local/lib/python3.12/site-packages/airflow/utils/session.py", line 97, in wrapper
    return func(*args, session=session, **kwargs)
           ^^^^^^^^^^^^^^^^^^^^^^^^^^^^^^^^^^^^^^
  File "/home/airflow/.local/lib/python3.12/site-packages/airflow/models/taskinstance.py", line 3006, in _run_raw_task
    return _run_raw_task(
           ^^^^^^^^^^^^^^
  File "/home/airflow/.local/lib/python3.12/site-packages/airflow/models/taskinstance.py", line 274, in _run_raw_task
    TaskInstance._execute_task_with_callbacks(
  File "/home/airflow/.local/lib/python3.12/site-packages/airflow/models/taskinstance.py", line 3161, in _execute_task_with_callbacks
    result = self._execute_task(context, task_orig)
             ^^^^^^^^^^^^^^^^^^^^^^^^^^^^^^^^^^^^^^
  File "/home/airflow/.local/lib/python3.12/site-packages/airflow/models/taskinstance.py", line 3185, in _execute_task
    return _execute_task(self, context, task_orig)
           ^^^^^^^^^^^^^^^^^^^^^^^^^^^^^^^^^^^^^^^
  File "/home/airflow/.local/lib/python3.12/site-packages/airflow/models/taskinstance.py", line 768, in _execute_task
    result = _execute_callable(context=context, **execute_callable_kwargs)
             ^^^^^^^^^^^^^^^^^^^^^^^^^^^^^^^^^^^^^^^^^^^^^^^^^^^^^^^^^^^^^
  File "/home/airflow/.local/lib/python3.12/site-packages/airflow/models/taskinstance.py", line 734, in _execute_callable
    return ExecutionCallableRunner(
           ^^^^^^^^^^^^^^^^^^^^^^^^
  File "/home/airflow/.local/lib/python3.12/site-packages/airflow/utils/operator_helpers.py", line 252, in run
    return self.func(*args, **kwargs)
           ^^^^^^^^^^^^^^^^^^^^^^^^^^
  File "/home/airflow/.local/lib/python3.12/site-packages/airflow/models/baseoperator.py", line 424, in wrapper
    return func(self, *args, **kwargs)
           ^^^^^^^^^^^^^^^^^^^^^^^^^^^
  File "/home/airflow/.local/lib/python3.12/site-packages/airflow/decorators/base.py", line 266, in execute
    return_value = super().execute(context)
                   ^^^^^^^^^^^^^^^^^^^^^^^^
  File "/home/airflow/.local/lib/python3.12/site-packages/airflow/models/baseoperator.py", line 424, in wrapper
    return func(self, *args, **kwargs)
           ^^^^^^^^^^^^^^^^^^^^^^^^^^^
  File "/home/airflow/.local/lib/python3.12/site-packages/airflow/operators/python.py", line 238, in execute
    return_value = self.execute_callable()
                   ^^^^^^^^^^^^^^^^^^^^^^^
  File "/home/airflow/.local/lib/python3.12/site-packages/airflow/operators/python.py", line 256, in execute_callable
    return runner.run(*self.op_args, **self.op_kwargs)
           ^^^^^^^^^^^^^^^^^^^^^^^^^^^^^^^^^^^^^^^^^^^
  File "/home/airflow/.local/lib/python3.12/site-packages/airflow/utils/operator_helpers.py", line 252, in run
    return self.func(*args, **kwargs)
           ^^^^^^^^^^^^^^^^^^^^^^^^^^
  File "/opt/airflow/dags/etl.py", line 64, in extract_review_data
    reviews_dataset = load_dataset("McAuley-Lab/Amazon-Reviews-2023", "raw_review_Kindle_Store", trust_remote_code=True,num_proc=64,split = 'full')
                      ^^^^^^^^^^^^^^^^^^^^^^^^^^^^^^^^^^^^^^^^^^^^^^^^^^^^^^^^^^^^^^^^^^^^^^^^^^^^^^^^^^^^^^^^^^^^^^^^^^^^^^^^^^^^^^^^^^^^^^^^^^^^^
  File "/home/airflow/.local/lib/python3.12/site-packages/datasets/load.py", line 2084, in load_dataset
    builder_instance.download_and_prepare(
  File "/home/airflow/.local/lib/python3.12/site-packages/datasets/builder.py", line 925, in download_and_prepare
    self._download_and_prepare(
  File "/home/airflow/.local/lib/python3.12/site-packages/datasets/builder.py", line 1649, in _download_and_prepare
    super()._download_and_prepare(
  File "/home/airflow/.local/lib/python3.12/site-packages/datasets/builder.py", line 979, in _download_and_prepare
    split_generators = self._split_generators(dl_manager, **split_generators_kwargs)
                       ^^^^^^^^^^^^^^^^^^^^^^^^^^^^^^^^^^^^^^^^^^^^^^^^^^^^^^^^^^^^^
  File "/home/airflow/.cache/huggingface/modules/datasets_modules/datasets/McAuley-Lab--Amazon-Reviews-2023/16b76e0823d73bb8cff1e9c5e3e37dbc46ae3daee380417ae141f5e67d3ea8e8/Amazon-Reviews-2023.py", line 509, in _split_generators
    dl_dir = dl_manager.download_and_extract(self.config.data_dir)
             ^^^^^^^^^^^^^^^^^^^^^^^^^^^^^^^^^^^^^^^^^^^^^^^^^^^^^
  File "/home/airflow/.local/lib/python3.12/site-packages/datasets/download/download_manager.py", line 326, in download_and_extract
    return self.extract(self.download(url_or_urls))
                        ^^^^^^^^^^^^^^^^^^^^^^^^^^
  File "/home/airflow/.local/lib/python3.12/site-packages/datasets/download/download_manager.py", line 159, in download
    downloaded_path_or_paths = map_nested(
                               ^^^^^^^^^^^
  File "/home/airflow/.local/lib/python3.12/site-packages/datasets/utils/py_utils.py", line 486, in map_nested
    mapped = function(data_struct)
             ^^^^^^^^^^^^^^^^^^^^^
  File "/home/airflow/.local/lib/python3.12/site-packages/datasets/download/download_manager.py", line 220, in _download_batched
    self._download_single(url_or_filename, download_config=download_config)
  File "/home/airflow/.local/lib/python3.12/site-packages/datasets/download/download_manager.py", line 229, in _download_single
    out = cached_path(url_or_filename, download_config=download_config)
          ^^^^^^^^^^^^^^^^^^^^^^^^^^^^^^^^^^^^^^^^^^^^^^^^^^^^^^^^^^^^^
  File "/home/airflow/.local/lib/python3.12/site-packages/datasets/utils/file_utils.py", line 189, in cached_path
    ).hf_hub_download(
      ^^^^^^^^^^^^^^^^
  File "/home/airflow/.local/lib/python3.12/site-packages/huggingface_hub/utils/_validators.py", line 114, in _inner_fn
    return fn(*args, **kwargs)
           ^^^^^^^^^^^^^^^^^^^
  File "/home/airflow/.local/lib/python3.12/site-packages/huggingface_hub/hf_api.py", line 5475, in hf_hub_download
    return hf_hub_download(
           ^^^^^^^^^^^^^^^^
  File "/home/airflow/.local/lib/python3.12/site-packages/huggingface_hub/utils/_validators.py", line 114, in _inner_fn
    return fn(*args, **kwargs)
           ^^^^^^^^^^^^^^^^^^^
  File "/home/airflow/.local/lib/python3.12/site-packages/huggingface_hub/file_download.py", line 961, in hf_hub_download
    return _hf_hub_download_to_cache_dir(
           ^^^^^^^^^^^^^^^^^^^^^^^^^^^^^^
  File "/home/airflow/.local/lib/python3.12/site-packages/huggingface_hub/file_download.py", line 1112, in _hf_hub_download_to_cache_dir
    _download_to_tmp_and_move(
  File "/home/airflow/.local/lib/python3.12/site-packages/huggingface_hub/file_download.py", line 1675, in _download_to_tmp_and_move
    http_get(
  File "/home/airflow/.local/lib/python3.12/site-packages/huggingface_hub/file_download.py", line 466, in http_get
    return http_get(
           ^^^^^^^^^
  File "/home/airflow/.local/lib/python3.12/site-packages/huggingface_hub/file_download.py", line 466, in http_get
    return http_get(
           ^^^^^^^^^
  File "/home/airflow/.local/lib/python3.12/site-packages/huggingface_hub/file_download.py", line 376, in http_get
    r = _request_wrapper(
        ^^^^^^^^^^^^^^^^^
  File "/home/airflow/.local/lib/python3.12/site-packages/huggingface_hub/file_download.py", line 309, in _request_wrapper
    hf_raise_for_status(response)
  File "/home/airflow/.local/lib/python3.12/site-packages/huggingface_hub/utils/_http.py", line 473, in hf_raise_for_status
    raise _format(HfHubHTTPError, message, response) from e
huggingface_hub.errors.HfHubHTTPError: 403 Forbidden: None.
Cannot access content at: https://cdn-lfs-us-1.hf.co/repos/e9/40/e940a8d106b2e3986d1f8b7626c5a3f4fced3c1f43b992d12b1d465b58efc824/82024e17fdd988f47d8b5ae679643965255ae5164f9f494d6ba28ab9cc0efa76?response-content-disposition=inline%3B+filename*%3DUTF-8%27%27Kindle_Store.jsonl%3B+filename%3D%22Kindle_Store.jsonl%22%3B&Expires=1745112024&Policy=eyJTdGF0ZW1lbnQiOlt7IkNvbmRpdGlvbiI6eyJEYXRlTGVzc1RoYW4iOnsiQVdTOkVwb2NoVGltZSI6MTc0NTExMjAyNH19LCJSZXNvdXJjZSI6Imh0dHBzOi8vY2RuLWxmcy11cy0xLmhmLmNvL3JlcG9zL2U5LzQwL2U5NDBhOGQxMDZiMmUzOTg2ZDFmOGI3NjI2YzVhM2Y0ZmNlZDNjMWY0M2I5OTJkMTJiMWQ0NjViNThlZmM4MjQvODIwMjRlMTdmZGQ5ODhmNDdkOGI1YWU2Nzk2NDM5NjUyNTVhZTUxNjRmOWY0OTRkNmJhMjhhYjljYzBlZmE3Nj9yZXNwb25zZS1jb250ZW50LWRpc3Bvc2l0aW9uPSoifV19&Signature=UWoQgmhxEMvSQhFak3bl8H7cGDXgy~BK51wPqucmvnekyNahkT5WN6I07hX93UHmgogUarwdfB6Bl3Eqg~xTKU-TWlER-yZKGHQ3sZDBExPSlXRtHfN-Nmj6cZbNhuHGLEa-v8nGAB98H7twfKEAKjFuSxRBlp0~39a-5yMyl6PUVPZ9PFQfJ76z17xcNijmiMEOwUSLUUXIEDXQoLQIKqCAZYVosLchyNA8KjlzWGeTOflr6sUB4rg4z9lgh7ESa-4JE3evLLaQFIjAmgI1Ba59SHolouZYgWsAnNKt-ZSE8Od4zGb9K31qhzUvfWrst0eBLRHXZ6HZUZ-MoTX3ww__&Key-Pair-Id=K24J24Z295AEI9.
Make sure your token has the correct permissions.
<?xml version="1.0" encoding="UTF-8"?><Error><Code>AccessDenied</Code><Message>Access denied</Message></Error>
[2025-04-20T01:21:32.519+0000] {local_task_job_runner.py:266} INFO - Task exited with return code 1
[2025-04-20T01:21:32.530+0000] {taskinstance.py:3901} INFO - 0 downstream tasks scheduled from follow-on schedule check
[2025-04-20T01:21:32.531+0000] {local_task_job_runner.py:245} INFO - ::endgroup::
